Workbook

Sheet 【2024年】前向收入合同审签表
A1: 前向收入合同审签表
A2: 收入确认计划 | B2: 必填 | C2: 选择填列 | D2: 必选 | E2: 自动带出 可修改 | F2: 自动带出 | G2: 选择填列 | H2: 自动带出 | I2: 选择填列 | J2: 自动带出 | K2: 必填 | L2: 选择填列 | M2: 自动带出 | N2: 自动带出 可修改 | O2: 收入确认计划 | P2: 必填 | Q2: 必选 | R2: 自动带出 可修改 | S2: 自动带出 | T2: 选择填列 | U2: 自动带出 | V2: 选择填列 | W2: 自动带出 | X2: 必填 | Y2: 必填 | Z2: 必填 | AA2: 公式自动算出 | AB2: 自动带出 | AC2: 自动带出 可修改
A3: 非周期性 序号 | B3: 预计确认日期 YYYY-MM-DD | C3: 业务模式 ICT净额列收才填 | D3: 集团产品名称 | E3: 集团产品收入项 | F3: 速率/带宽 填写提示 （在G列）→ | G3: 速率/带宽 收入项为电路及专线必填 | H3: 折扣率 填写提示 （在I列）→ | I3: 折扣率 物联网卡必填 | J3: 税率 | K3: 计划确认总金额 (含税) | L3: 跨省省份名称 跨省电路业务必填 按分摊金额分开填列 | M3: 是否 网元开通 | N3: 是否CRM 确认收入 | O3: 周期性 序号 | P3: 起始日期 YYYY-MM-DD | Q3: 集团产品名称 | R3: 集团产品收入项 | S3: 速率/带宽 填写提示 (在T列）→ | T3: 速率/带宽 收入项为电路及专线必填 | U3: 折扣率 填写提示 (在V列）→ | V3: 折扣率 物联网卡必填 | W3: 税率 | X3: 收入确认 总时长 （月） | Y3: 每月单价 | Z3: 产品数量 | AA3: 确认总金额 (含税) | AB3: 是否 网元开通 | AC3: 是否CRM 确认收入
A4: 1 | E4: =IFERROR(VLOOKUP(D4,【2024年】集团产品与集团产品收入项配置表!$D:$R,9,FALSE),"选择集团产品名称后自动带出") -> 选择集团产品名称后自动带出 | F4: =IFERROR(VLOOKUP(D4,【2024年】集团产品与集团产品收入项配置表!$D:$T,16,FALSE),"选择集团产品名称后自动带出") -> 选择集团产品名称后自动带出 | H4: =IFERROR(VLOOKUP(D4,【2024年】集团产品与集团产品收入项配置表!$D:$T,17,FALSE),"选择集团产品名称后自动带出") -> 选择集团产品名称后自动带出 | J4: =IFERROR(VLOOKUP(D4,【2024年】集团产品与集团产品收入项配置表!$D:$R,10,FALSE),"选择集团产品名称后自动带出") -> 选择集团产品名称后自动带出 | M4: =IFERROR(VLOOKUP(D4,【2024年】集团产品与集团产品收入项配置表!$D:$R,14,FALSE),"选择集团产品名称后自动带出") -> 选择集团产品名称后自动带出 | N4: =IFERROR(VLOOKUP(D4,【2024年】集团产品与集团产品收入项配置表!$D:$R,15,FALSE),"选择集团产品名称后自动带出") -> 选择集团产品名称后自动带出 | O4: 1 | R4: =IFERROR(VLOOKUP(Q4,【2024年】集团产品与集团产品收入项配置表!$D:$R,9,FALSE),"选择集团产品名称后自动带出") -> 选择集团产品名称后自动带出 | S4: =IFERROR(VLOOKUP(Q4,【2024年】集团产品与集团产品收入项配置表!$D:$T,16,FALSE),"选择集团产品名称后自动带出") -> 选择集团产品名称后自动带出 | U4: =IFERROR(VLOOKUP(Q4,【2024年】集团产品与集团产品收入项配置表!$D:$T,17,FALSE),"选择集团产品名称后自动带出") -> 选择集团产品名称后自动带出 | W4: =IFERROR(VLOOKUP(Q4,【2024年】集团产品与集团产品收入项配置表!$D:$R,10,FALSE),"选择集团产品名称后自动带出") -> 选择集团产品名称后自动带出 | AA4: =Y4*Z4*X4 -> 0 | AB4: =IFERROR(VLOOKUP(Q4,【2024年】集团产品与集团产品收入项配置表!$D:$R,14,FALSE),"选择集团产品名称后自动带出") -> 选择集团产品名称后自动带出 | AC4: =IFERROR(VLOOKUP(Q4,【2024年】集团产品与集团产品收入项配置表!$D:$R,15,FALSE),"选择集团产品名称后自动带出") -> 选择集团产品名称后自动带出
A5: 2 | E5: =IFERROR(VLOOKUP(D5,【2024年】集团产品与集团产品收入项配置表!$D:$R,9,FALSE),"选择集团产品名称后自动带出") -> 选择集团产品名称后自动带出 | F5: =IFERROR(VLOOKUP(D5,【2024年】集团产品与集团产品收入项配置表!$D:$T,16,FALSE),"选择集团产品名称后自动带出") -> 选择集团产品名称后自动带出 | H5: =IFERROR(VLOOKUP(D5,【2024年】集团产品与集团产品收入项配置表!$D:$T,17,FALSE),"选择集团产品名称后自动带出") -> 选择集团产品名称后自动带出 | J5: =IFERROR(VLOOKUP(D5,【2024年】集团产品与集团产品收入项配置表!$D:$R,10,FALSE),"选择集团产品名称后自动带出") -> 选择集团产品名称后自动带出 | M5: =IFERROR(VLOOKUP(D5,【2024年】集团产品与集团产品收入项配置表!$D:$R,14,FALSE),"选择集团产品名称后自动带出") -> 选择集团产品名称后自动带出 | N5: =IFERROR(VLOOKUP(D5,【2024年】集团产品与集团产品收入项配置表!$D:$R,15,FALSE),"选择集团产品名称后自动带出") -> 选择集团产品名称后自动带出 | O5: 2 | R5: =IFERROR(VLOOKUP(Q5,【2024年】集团产品与集团产品收入项配置表!$D:$R,9,FALSE),"选择集团产品名称后自动带出") -> 选择集团产品名称后自动带出 | S5: =IFERROR(VLOOKUP(Q5,【2024年】集团产品与集团产品收入项配置表!$D:$T,16,FALSE),"选择集团产品名称后自动带出") -> 选择集团产品名称后自动带出 | U5: =IFERROR(VLOOKUP(Q5,【2024年】集团产品与集团产品收入项配置表!$D:$T,17,FALSE),"选择集团产品名称后自动带出") -> 选择集团产品名称后自动带出 | W5: =IFERROR(VLOOKUP(Q5,【2024年】集团产品与集团产品收入项配置表!$D:$R,10,FALSE),"选择集团产品名称后自动带出") -> 选择集团产品名称后自动带出 | AA5: =Y5*Z5*X5 -> 0 | AB5: =IFERROR(VLOOKUP(Q5,【2024年】集团产品与集团产品收入项配置表!$D:$R,14,FALSE),"选择集团产品名称后自动带出") -> 选择集团产品名称后自动带出 | AC5: =IFERROR(VLOOKUP(Q5,【2024年】集团产品与集团产品收入项配置表!$D:$R,15,FALSE),"选择集团产品名称后自动带出") -> 选择集团产品名称后自动带出
A6: 3 | E6: =IFERROR(VLOOKUP(D6,【2024年】集团产品与集团产品收入项配置表!$D:$R,9,FALSE),"选择集团产品名称后自动带出") -> 选择集团产品名称后自动带出 | F6: =IFERROR(VLOOKUP(D6,【2024年】集团产品与集团产品收入项配置表!$D:$T,16,FALSE),"选择集团产品名称后自动带出") -> 选择集团产品名称后自动带出 | H6: =IFERROR(VLOOKUP(D6,【2024年】集团产品与集团产品收入项配置表!$D:$T,17,FALSE),"选择集团产品名称后自动带出") -> 选择集团产品名称后自动带出 | J6: =IFERROR(VLOOKUP(D6,【2024年】集团产品与集团产品收入项配置表!$D:$R,10,FALSE),"选择集团产品名称后自动带出") -> 选择集团产品名称后自动带出 | M6: =IFERROR(VLOOKUP(D6,【2024年】集团产品与集团产品收入项配置表!$D:$R,14,FALSE),"选择集团产品名称后自动带出") -> 选择集团产品名称后自动带出 | N6: =IFERROR(VLOOKUP(D6,【2024年】集团产品与集团产品收入项配置表!$D:$R,15,FALSE),"选择集团产品名称后自动带出") -> 选择集团产品名称后自动带出 | O6: 3 | R6: =IFERROR(VLOOKUP(Q6,【2024年】集团产品与集团产品收入项配置表!$D:$R,9,FALSE),"选择集团产品名称后自动带出") -> 选择集团产品名称后自动带出 | S6: =IFERROR(VLOOKUP(Q6,【2024年】集团产品与集团产品收入项配置表!$D:$T,16,FALSE),"选择集团产品名称后自动带出") -> 选择集团产品名称后自动带出 | U6: =IFERROR(VLOOKUP(Q6,【2024年】集团产品与集团产品收入项配置表!$D:$T,17,FALSE),"选择集团产品名称后自动带出") -> 选择集团产品名称后自动带出 | W6: =IFERROR(VLOOKUP(Q6,【2024年】集团产品与集团产品收入项配置表!$D:$R,10,FALSE),"选择集团产品名称后自动带出") -> 选择集团产品名称后自动带出 | AA6: =Y6*Z6*X6 -> 0 | AB6: =IFERROR(VLOOKUP(Q6,【2024年】集团产品与集团产品收入项配置表!$D:$R,14,FALSE),"选择集团产品名称后自动带出") -> 选择集团产品名称后自动带出 | AC6: =IFERROR(VLOOKUP(Q6,【2024年】集团产品与集团产品收入项配置表!$D:$R,15,FALSE),"选择集团产品名称后自动带出") -> 选择集团产品名称后自动带出
A7: 4 | E7: =IFERROR(VLOOKUP(D7,【2024年】集团产品与集团产品收入项配置表!$D:$R,9,FALSE),"选择集团产品名称后自动带出") -> 选择集团产品名称后自动带出 | F7: =IFERROR(VLOOKUP(D7,【2024年】集团产品与集团产品收入项配置表!$D:$T,16,FALSE),"选择集团产品名称后自动带出") -> 选择集团产品名称后自动带出 | H7: =IFERROR(VLOOKUP(D7,【2024年】集团产品与集团产品收入项配置表!$D:$T,17,FALSE),"选择集团产品名称后自动带出") -> 选择集团产品名称后自动带出 | J7: =IFERROR(VLOOKUP(D7,【2024年】集团产品与集团产品收入项配置表!$D:$R,10,FALSE),"选择集团产品名称后自动带出") -> 选择集团产品名称后自动带出 | M7: =IFERROR(VLOOKUP(D7,【2024年】集团产品与集团产品收入项配置表!$D:$R,14,FALSE),"选择集团产品名称后自动带出") -> 选择集团产品名称后自动带出 | N7: =IFERROR(VLOOKUP(D7,【2024年】集团产品与集团产品收入项配置表!$D:$R,15,FALSE),"选择集团产品名称后自动带出") -> 选择集团产品名称后自动带出 | O7: 4 | R7: =IFERROR(VLOOKUP(Q7,【2024年】集团产品与集团产品收入项配置表!$D:$R,9,FALSE),"选择集团产品名称后自动带出") -> 选择集团产品名称后自动带出 | S7: =IFERROR(VLOOKUP(Q7,【2024年】集团产品与集团产品收入项配置表!$D:$T,16,FALSE),"选择集团产品名称后自动带出") -> 选择集团产品名称后自动带出 | U7: =IFERROR(VLOOKUP(Q7,【2024年】集团产品与集团产品收入项配置表!$D:$T,17,FALSE),"选择集团产品名称后自动带出") -> 选择集团产品名称后自动带出 | W7: =IFERROR(VLOOKUP(Q7,【2024年】集团产品与集团产品收入项配置表!$D:$R,10,FALSE),"选择集团产品名称后自动带出") -> 选择集团产品名称后自动带出 | AA7: =Y7*Z7*X7 -> 0 | AB7: =IFERROR(VLOOKUP(Q7,【2024年】集团产品与集团产品收入项配置表!$D:$R,14,FALSE),"选择集团产品名称后自动带出") -> 选择集团产品名称后自动带出 | AC7: =IFERROR(VLOOKUP(Q7,【2024年】集团产品与集团产品收入项配置表!$D:$R,15,FALSE),"选择集团产品名称后自动带出") -> 选择集团产品名称后自动带出
A8: 5 | E8: =IFERROR(VLOOKUP(D8,【2024年】集团产品与集团产品收入项配置表!$D:$R,9,FALSE),"选择集团产品名称后自动带出") -> 选择集团产品名称后自动带出 | F8: =IFERROR(VLOOKUP(D8,【2024年】集团产品与集团产品收入项配置表!$D:$T,16,FALSE),"选择集团产品名称后自动带出") -> 选择集团产品名称后自动带出 | H8: =IFERROR(VLOOKUP(D8,【2024年】集团产品与集团产品收入项配置表!$D:$T,17,FALSE),"选择集团产品名称后自动带出") -> 选择集团产品名称后自动带出 | J8: =IFERROR(VLOOKUP(D8,【2024年】集团产品与集团产品收入项配置表!$D:$R,10,FALSE),"选择集团产品名称后自动带出") -> 选择集团产品名称后自动带出 | M8: =IFERROR(VLOOKUP(D8,【2024年】集团产品与集团产品收入项配置表!$D:$R,14,FALSE),"选择集团产品名称后自动带出") -> 选择集团产品名称后自动带出 | N8: =IFERROR(VLOOKUP(D8,【2024年】集团产品与集团产品收入项配置表!$D:$R,15,FALSE),"选择集团产品名称后自动带出") -> 选择集团产品名称后自动带出 | O8: 5 | R8: =IFERROR(VLOOKUP(Q8,【2024年】集团产品与集团产品收入项配置表!$D:$R,9,FALSE),"选择集团产品名称后自动带出") -> 选择集团产品名称后自动带出 | S8: =IFERROR(VLOOKUP(Q8,【2024年】集团产品与集团产品收入项配置表!$D:$T,16,FALSE),"选择集团产品名称后自动带出") -> 选择集团产品名称后自动带出 | U8: =IFERROR(VLOOKUP(Q8,【2024年】集团产品与集团产品收入项配置表!$D:$T,17,FALSE),"选择集团产品名称后自动带出") -> 选择集团产品名称后自动带出 | W8: =IFERROR(VLOOKUP(Q8,【2024年】集团产品与集团产品收入项配置表!$D:$R,10,FALSE),"选择集团产品名称后自动带出") -> 选择集团产品名称后自动带出 | AA8: =Y8*Z8*X8 -> 0 | AB8: =IFERROR(VLOOKUP(Q8,【2024年】集团产品与集团产品收入项配置表!$D:$R,14,FALSE),"选择集团产品名称后自动带出") -> 选择集团产品名称后自动带出 | AC8: =IFERROR(VLOOKUP(Q8,【2024年】集团产品与集团产品收入项配置表!$D:$R,15,FALSE),"选择集团产品名称后自动带出") -> 选择集团产品名称后自动带出
A9: 合 计 | K9: =SUM(K4:K8) -> 0 | O9: 合 计 | AA9: =SUM(AA4:AA8) -> 0
A11: 是否有 履约保证金 | C11: 是否有 维保要求 | E11: 是否有 审计条款 | G11: 发票种类 （必选） | H11: 增值税专用发票 | I11: 该合同实际 利润归属单位 （必选） | J11: 政企事业群
A13: 收款计划 | B13: 必填 | C13: 必选 | D13: 必填 | E13: 必选 | F13: 按比例收款 时必填 | G13: 必填 | H13: 必选 | I13: 收款计划 | J13: 必填 | K13: 必选 | L13: 必填 | M13: 必填 | N13: 公式自动算出 | O13: 必选
A14: 非周期性 序号 | B14: 预计收款日期 YYYY-MM-DD | C14: 非周期 收款方式 | D14: 第N次 | E14: 履行要求 | F14: 约定收款 比例 | G14: 约定收款 金额 | H14: 收款 触发系统 | I14: 周期性 序号 | J14: 预计收款 起始日期 YYYY-MM-DD | K14: 收款频率 （周期方式） | L14: 期数 | M14: 每期金额 | N14: 金额合计 | O14: 收款 触发系统
A15: 1 | I15: 1 | N15: =L15*M15 -> 0
A16: 2 | I16: 2 | N16: =L16*M16 -> 0
A17: 3 | I17: 3 | N17: =L17*M17 -> 0
A18: 4 | I18: 4 | N18: =L18*M18 -> 0
A19: 5 | I19: 5 | N19: =L19*M19 -> 0
A20: 合 计 | F20: =SUM(F15:F19) -> 0 | G20: =SUM(G15:G19) -> 0 | I20: 合 计 | N20: =SUM(N15:N19) -> 0
A22: 填表人： （必填） | B22: 王照龙 | C22: 联系方式： （必填） | D22: 02152927531 | E22: 项目立项人: （必填） | F22: 王照龙 | G22: 联系方式： （必填） | H22: 02152927531
A25: 填表说明：
A26: 1、若涉及多项产品收入项的请分行填列，小计金额需与合同金额一致。
A27: 2、若合同履约信息即有非周期性也有周期性，则在相应表格中填列。
A28: 3、若该合同有跨利润中心的情况，请填列“该合同实际利润归属单位”信息，不然合同解析利润中心默认为合同发起单位。
A29: 4、若非周期收款方式为按金额收款的，表格中约定收款比例可不填列。
A30: 5、“是否有履约保证金”、“是否有维保要求”及“是否有审计条款”默认为“否”，若该合同涉及此3项有实际发生的请改为“是”并附相应情况说明。
A31: 6、由于目前部分产品较个性化，不具备标准化资费的条件，无法走CRM系统开账，而通过聚焦系统开账会虚增应收账款，因此选“非CRM确认收入”的合同，其实际履约信息若为周期性的，一律解析为非周期性。
A32: 7、集团要求按月确认收入的为收入周期性，除此之外均为非周期性收入；而收款方式的频率若为按月、按季、按半年、按年则均为周期性收款。
A33: 8、集团要求涉及电路及专线类收入项的话，速率及带宽为必填，涉及物联网收入项的话，折扣率为必填。
A34: 9、跨省电路业务新增“跨省省份”列，请按分摊金额分开填列。

Sheet 【2024年】集团产品与集团产品收入项配置表
A1: 产品大类编码（修订） | B1: 产品大类（修订） | C1: 产品编码 | D1: 产品名称 | E1: 是否ICT产品 | F1: 单位 | G1: 注释 | H1: 产品类型 | I1: 产品类别 | J1: 平台类型编码 | K1: 平台类型 名称 | L1: 默认带出的产品收入项2024 | M1: 税率 | N1: 默认带出的产品收入项名称2024 | O1: 可选产品收入项范围编码2024 | P1: 可选产品收入项范围2024 | Q1: 是否网元 | R1: 是否触发CRM | S1: 速率/带宽 填写提示 | T1: 折扣率 填写提示 | U1: 删除状态 | V1: V1.1-2024年更新情况
A2: JTSJCPDL201908 | B2: 电路业务 | C2: JTSJCP02041 | D2: IP虚拟专网（MPLS VPN） | E2: 否 | F2: 条 | G2: 线路数 | H2: 外延业务 | I2: 电路 | K2: 专线接入成本 | L2: 1563 | M2: 0.09 | N2: 产业数字化-行业网络服务-普通组网专线-IP虚拟专网-大陆境内 | O2: 1563;1565;1566 | P2: 产业数字化-行业网络服务-组网专线-普通组网专线-IP虚拟专网-大陆境内;产业数字化-行业网络服务-组网专线-普通组网专线-IP虚拟专网-国际及港澳台-境内客户;产业数字化-行业网络服务-组网专线-普通组网专线-IP虚拟专网-国际及港澳台-境外客户 | Q2: 是 | R2: 是 | S2: 需填写速率/带宽 | T2: 无需填写折扣率
A3: JTSJCPDL201909 | B3: 专线业务 | C3: JTSJCP02042 | D3: 互联网专线-500M及以上 | E3: 否 | F3: 条 | G3: 线路数 | H3: 外延业务 | I3: 专线 | K3: 专线接入成本 | L3: 1320 | M3: 0.06 | N3: 固网及智慧家庭服务-互联网宽带接入-互联网专线-普通国内互联网专线收入-FTTH/O | O3: 1306;1307;1320;1321;1322;1323;1326;1329;1330;1331;2557 | P3: 固网及智慧家庭服务-互联网宽带接入-普通宽带-装移机收入;固网及智慧家庭服务-互联网宽带接入-普通宽带-业务调测费;固网及智慧家庭服务-互联网宽带接入-互联网专线-普通国内互联网专线收入-FTTH/O;固网及智慧家庭服务-互联网宽带接入-互联网专线-普通国内互联网专线收入-ADSL;固网及智慧家庭服务-互联网宽带接入-互联网专线-普通国内互联网专线收入-LAN;固网及智慧家庭服务-互联网宽带接入-互联网专线-普通国内互联网专线收入-光纤直驱;固网及智慧家庭服务-行业类固网产品-互联网专线安全服务（云堤）-其他;固网及智慧家庭服务-行业类固网产品-互联网专线安全服务（云堤）-DDoS攻击防护服务（互联网）;固网及智慧家庭服务-互联网宽带接入-互联网专线-商务专线;固网及智慧家庭服务-互联网宽带接入-互联网专线-国际精品专线;固网及智慧家庭服务-互联网宽带接入-互联网专线-其他互联网宽带接入业务-其他 | Q3: 是 | R3: 是 | S3: 需填写速率/带宽 | T3: 无需填写折扣率 | V3: 可选1332删除，映射2557
A4: JTSJCPDL201909 | B4: 专线业务 | C4: JTSJCP02108 | D4: 互联网专线-500M以下 | E4: 否 | F4: 条 | G4: 线路数 | H4: 外延业务 | I4: 专线 | K4: 专线接入成本 | L4: 1320 | M4: 0.06 | N4: 固网及智慧家庭服务-互联网宽带接入-互联网专线-普通国内互联网专线收入-FTTH/O | O4: 1306;1307;1320;1321;1322;1323;1326;1329;1330;1331;2557 | P4: 固网及智慧家庭服务-互联网宽带接入-普通宽带-装移机收入;固网及智慧家庭服务-互联网宽带接入-普通宽带-业务调测费;固网及智慧家庭服务-互联网宽带接入-互联网专线-普通国内互联网专线收入-FTTH/O;固网及智慧家庭服务-互联网宽带接入-互联网专线-普通国内互联网专线收入-ADSL;固网及智慧家庭服务-互联网宽带接入-互联网专线-普通国内互联网专线收入-LAN;固网及智慧家庭服务-互联网宽带接入-互联网专线-普通国内互联网专线收入-光纤直驱;固网及智慧家庭服务-行业类固网产品-互联网专线安全服务（云堤）-其他;固网及智慧家庭服务-行业类固网产品-互联网专线安全服务（云堤）-DDoS攻击防护服务（互联网）;固网及智慧家庭服务-互联网宽带接入-互联网专线-商务专线;固网及智慧家庭服务-互联网宽带接入-互联网专线-国际精品专线;固网及智慧家庭服务-互联网宽带接入-互联网专线-其他互联网宽带接入业务-其他 | Q4: 是 | R4: 是 | S4: 需填写速率/带宽 | T4: 无需填写折扣率 | V4: 可选1332删除，映射2557
A5: JTSJCPDL201909 | B5: 专线业务 | C5: JTSJCP02089 | D5: 互联网国际精品专线-500M及以上 | E5: 否 | F5: 条 | G5: 线路数 | H5: 外延业务 | I5: 专线 | K5: 专线接入成本 | L5: 1331 | M5: 0.06 | N5: 固网及智慧家庭服务-互联网宽带接入-互联网专线-国际精品专线 | O5: 1331 | P5: 固网及智慧家庭服务-互联网宽带接入-互联网专线-国际精品专线 | Q5: 是 | R5: 是 | S5: 需填写速率/带宽 | T5: 无需填写折扣率
A6: JTSJCPDL201909 | B6: 专线业务 | C6: JTSJCP02109 | D6: 互联网国际精品专线-500M以下 | E6: 否 | F6: 条 | G6: 线路数 | H6: 外延业务 | I6: 专线 | K6: 专线接入成本 | L6: 1331 | M6: 0.06 | N6: 固网及智慧家庭服务-互联网宽带接入-互联网专线-国际精品专线 | O6: 1331 | P6: 固网及智慧家庭服务-互联网宽带接入-互联网专线-国际精品专线 | Q6: 是 | R6: 是 | S6: 需填写速率/带宽 | T6: 无需填写折扣率
A7: JTSJCPDL201908 | B7: 电路业务 | C7: JTSJCP02048 | D7: 数字电路-省际长途 | E7: 否 | F7: 条 | G7: 线路数 | H7: 外延业务 | I7: 电路 | K7: 省际长途SDH电路 | L7: 1551 | M7: 0.09 | N7: 产业数字化-行业网络服务-普通组网专线-传输专线（SDH/MSTP/波分/ROADM）-大陆境内-长途 | O7: 1551 | P7: 产业数字化-行业网络服务-普通组网专线-传输专线（SDH/MSTP/波分/ROADM）-大陆境内-长途 | Q7: 是 | R7: 是 | S7: 需填写速率/带宽 | T7: 无需填写折扣率
A8: JTSJCPDL201908 | B8: 电路业务 | C8: JTSJCP02102 | D8: 数字电路-省内长途 | E8: 否 | F8: 条 | G8: 线路数 | H8: 外延业务 | I8: 电路 | K8: 省内长途SDH电路 | L8: 1551 | M8: 0.09 | N8: 产业数字化-行业网络服务-普通组网专线-传输专线（SDH/MSTP/波分/ROADM）-大陆境内-长途 | O8: 1551 | P8: 产业数字化-行业网络服务-普通组网专线-传输专线（SDH/MSTP/波分/ROADM）-大陆境内-长途 | Q8: 是 | R8: 是 | S8: 需填写速率/带宽 | T8: 无需填写折扣率
A9: JTSJCPDL201908 | B9: 电路业务 | C9: JTSJCP02103 | D9: 数字电路-本地电路 | E9: 否 | F9: 条 | G9: 线路数 | H9: 外延业务 | I9: 电路 | K9: 本地SDH电路 | L9: 1550 | M9: 0.09 | N9: 产业数字化-行业网络服务-普通组网专线-传输专线（SDH/MSTP/波分/ROADM）-大陆境内-本地 | O9: 1550 | P9: 产业数字化-行业网络服务-普通组网专线-传输专线（SDH/MSTP/波分/ROADM）-大陆境内-本地 | Q9: 是 | R9: 是 | S9: 需填写速率/带宽 | T9: 无需填写折扣率
A10: JTSJCPDL201908 | B10: 电路业务 | C10: JTSJCP02049 | D10: MSTP-省际长途 | E10: 否 | F10: 条 | G10: 线路数 | H10: 外延业务 | I10: 电路 | K10: 省际长途SDH电路 | L10: 1551 | M10: 0.09 | N10: 产业数字化-行业网络服务-普通组网专线-传输专线（SDH/MSTP/波分/ROADM）-大陆境内-长途 | O10: 1551 | P10: 产业数字化-行业网络服务-普通组网专线-传输专线（SDH/MSTP/波分/ROADM）-大陆境内-长途 | Q10: 是 | R10: 是 | S10: 需填写速率/带宽 | T10: 无需填写折扣率
A11: JTSJCPDL201908 | B11: 电路业务 | C11: JTSJCP02104 | D11: MSTP-省内长途 | E11: 否 | F11: 条 | G11: 线路数 | H11: 外延业务 | I11: 电路 | K11: 省内长途SDH电路 | L11: 1551 | M11: 0.09 | N11: 产业数字化-行业网络服务-普通组网专线-传输专线（SDH/MSTP/波分/ROADM）-大陆境内-长途 | O11: 1551 | P11: 产业数字化-行业网络服务-普通组网专线-传输专线（SDH/MSTP/波分/ROADM）-大陆境内-长途 | Q11: 是 | R11: 是 | S11: 需填写速率/带宽 | T11: 无需填写折扣率
A12: JTSJCPDL201908 | B12: 电路业务 | C12: JTSJCP02105 | D12: MSTP-本地电路 | E12: 否 | F12: 条 | G12: 线路数 | H12: 外延业务 | I12: 电路 | K12: 本地SDH电路 | L12: 1550 | M12: 0.09 | N12: 产业数字化-行业网络服务-普通组网专线-传输专线（SDH/MSTP/波分/ROADM）-大陆境内-本地 | O12: 1550 | P12: 产业数字化-行业网络服务-普通组网专线-传输专线（SDH/MSTP/波分/ROADM）-大陆境内-本地 | Q12: 是 | R12: 是 | S12: 需填写速率/带宽 | T12: 无需填写折扣率
A13: JTSJCPDL201908 | B13: 电路业务 | C13: JTSJCP02106 | D13: 大带宽传输专线-省内长途 | E13: 否 | F13: 条 | G13: 线路数 | H13: 外延业务 | I13: 电路 | K13: 省内长途WDM电路 | L13: 1551 | M13: 0.09 | N13: 产业数字化-行业网络服务-普通组网专线-传输专线（SDH/MSTP/波分/ROADM）-大陆境内-长途 | O13: 1551 | P13: 产业数字化-行业网络服务-普通组网专线-传输专线（SDH/MSTP/波分/ROADM）-大陆境内-长途 | Q13: 是 | R13: 是 | S13: 需填写速率/带宽 | T13: 无需填写折扣率
A14: JTSJCPDL201908 | B14: 电路业务 | C14: JTSJCP02107 | D14: 大带宽传输专线-本地电路 | E14: 否 | F14: 条 | G14: 线路数 | H14: 外延业务 | I14: 电路 | K14: 本地WDM电路 | L14: 1550 | M14: 0.09 | N14: 产业数字化-行业网络服务-普通组网专线-传输专线（SDH/MSTP/波分/ROADM）-大陆境内-本地 | O14: 1550 | P14: 产业数字化-行业网络服务-普通组网专线-传输专线（SDH/MSTP/波分/ROADM）-大陆境内-本地 | Q14: 是 | R14: 是 | S14: 需填写速率/带宽 | T14: 无需填写折扣率
A15: JTSJCPDL201910 | B15: 卫星业务 | C15: JTSJCP01051 | D15: 卫星移动 | E15: 否 | F15: 户 | G15: 拉动移动入网用户数 | H15: 外延业务 | I15: 专线 | L15: 1005 | M15: 0.06 | N15: 移动通信服务-移动语音-语音收入 | O15: 1005 | P15: 移动通信服务-移动语音-语音收入 | Q15: 是 | R15: 是 | S15: 无需填写速率/带宽 | T15: 无需填写折扣率
A16: JTSJCPDL201907 | B16: 物联网业务 | C16: JTSJCP04001 | D16: 物联网语音 | E16: 否 | F16: 户 | G16: 拉动移动入网用户数 | H16: 物联网 | I16: 物联网 | L16: 1714 | M16: 0.09 | N16: 产业数字化-行业网络服务-物联网-连接服务-语音 | O16: 1714 | P16: 产业数字化-行业网络服务-物联网-连接服务-语音 | Q16: 是 | R16: 是 | S16: 无需填写速率/带宽 | T16: 无需填写折扣率
A17: JTSJCPDL201907 | B17: 物联网业务 | C17: JTSJCP04002 | D17: 物联网流量 | E17: 否 | F17: 户 | G17: 拉动移动入网用户数 | H17: 物联网 | I17: 物联网 | L17: 1716 | M17: 0.06 | N17: 产业数字化-行业网络服务-物联网-连接服务-流量-定向流量 | O17: 1716 | P17: 产业数字化-行业网络服务-物联网-连接服务-流量-定向流量 | Q17: 是 | R17: 是 | S17: 无需填写速率/带宽 | T17: 需填写折扣率
A18: JTSJCPDL201907 | B18: 物联网业务 | C18: JTSJCP04003 | D18: 物联网短信 | E18: 否 | F18: 户 | G18: 拉动移动入网用户数 | H18: 物联网 | I18: 物联网 | L18: 1719 | M18: 0.06 | N18: 产业数字化-行业网络服务-物联网-连接服务-短信 | O18: 1719 | P18: 产业数字化-行业网络服务-物联网-连接服务-短信 | Q18: 是 | R18: 是 | S18: 无需填写速率/带宽 | T18: 无需填写折扣率
A19: JTSJCPDL201907 | B19: 物联网业务 | C19: JTSJCP04004 | D19: 物联网基础能力增值 | E19: 否 | F19: 户 | G19: 拉动移动入网用户数 | H19: 物联网 | I19: 物联网 | L19: 1720 | M19: 0.06 | N19: 产业数字化-行业网络服务-物联网-连接服务-增值 | O19: 1720 | P19: 产业数字化-行业网络服务-物联网-连接服务-增值 | Q19: 是 | R19: 是 | S19: 无需填写速率/带宽 | T19: 无需填写折扣率
A20: JTSJCPDL201907 | B20: 物联网业务 | C20: JTSJCP04005 | D20: 物联网应用 | E20: 否 | F20: 户 | G20: 拉动移动入网用户数 | H20: 物联网 | I20: 物联网 | L20: 2763 | M20: 0.06 | N20: 产业数字化-行业网络服务-物联网-应用服务-行业应用-其他 | O20: 2763 | P20: 产业数字化-行业网络服务-物联网-应用服务-行业应用-其他 | Q20: 是 | R20: 是 | S20: 无需填写速率/带宽 | T20: 无需填写折扣率 | V20: 删除，父级指标，映射2763
A21: JTSJCPDL201910 | B21: 卫星业务 | C21: JTSJCP02090 | D21: 卫星国内专线 | E21: 否 | F21: 条 | G21: 线路数 | H21: 外延业务 | I21: 专线 | K21: 专线接入成本 | L21: 1301 | M21: 0.06 | N21: 固网及智慧家庭服务-互联网宽带接入-卫星宽带-卫星宽带服务 | O21: 1301;1302; | P21: 固网及智慧家庭服务-互联网宽带接入-卫星宽带-卫星宽带服务;固网及智慧家庭服务-互联网宽带接入-卫星宽带-卫星资源服务 | Q21: 是 | R21: 是 | S21: 需填写速率/带宽 | T21: 无需填写折扣率
A22: JTSJCPDL201914 | B22: 其它业务 | C22: JTSJCP03007 | D22: 房屋出租 | E22: 否 | F22: - | G22: - | H22: 房屋租赁 | L22: 1763 | M22: 9%;5% | N22: 其他-固网其他-出租房产场地收入 | O22: 1763 | P22: 其他-固网其他-出租房产场地收入 | Q22: 否 | R22: 否 | S22: 无需填写速率/带宽 | T22: 无需填写折扣率
A23: JTSJCPDL201911 | B23: 基础移动业务 | C23: JTSJCP01001 | D23: 移动单机业务 | E23: 否 | F23: 户 | G23: 拉动移动入网用户数 | H23: 外延业务 | J23: 040229 | K23: 移动业务户均成本 | L23: 1005 | M23: 0.06 | N23: 移动通信服务-移动语音-语音收入 | O23: 1005 | P23: 移动通信服务-移动语音-语音收入 | Q23: 是 | R23: 是 | S23: 无需填写速率/带宽 | T23: 无需填写折扣率
A24: JTSJCPDL201912 | B24: 增值业务 | C24: JTSJCP01002 | D24: 总机服务 | E24: 否 | F24: 户 | G24: 开通功能的用户数 | H24: 外延业务 | L24: 1289 | M24: 0.06 | N24: 固网及智慧家庭服务-固定电话-固话信息产品及增值服务-企业总机-收入（大收） | O24: 1289 | P24: 固网及智慧家庭服务-固定电话-固话信息产品及增值服务-企业总机-收入（大收） | Q24: 是 | R24: 是 | S24: 无需填写速率/带宽 | T24: 无需填写折扣率 | V24: 删除，映射1289
A25: JTSJCPDL201905 | B25: ICT-行业应用 | C25: JTSJCP01003 | D25: 加密通信 | E25: 是 | F25: 户 | G25: 开通功能的用户数 | H25: 行业应用 | I25: ICT | L25: 1637 | M25: 0.06 | N25: 产业数字化-平台（大平台）-行业平台及应用-行业信息化应用-加密通信（净收） | O25: 1637 | P25: 产业数字化-平台（大平台）-行业平台及应用-行业信息化应用-加密通信（净收） | Q25: 是 | R25: 是 | S25: 无需填写速率/带宽 | T25: 无需填写折扣率
A26: JTSJCPDL201905 | B26: ICT-行业应用 | C26: JTSJCP01004 | D26: 销售管家 | E26: 是 | F26: 户 | G26: 开通功能的用户数 | H26: 行业应用 | I26: ICT | J26: 040222 | K26: 行业应用类平台(销售管家) | L26: 1590 | M26: 0.06 | N26: 产业数字化-平台（大平台）-行业平台及应用-行业平台-工业互联网平台应用 | O26: 1590 | P26: 产业数字化-平台（大平台）-行业平台及应用-行业平台-工业互联网平台应用 | Q26: 是 | R26: 是 | S26: 无需填写速率/带宽 | T26: 无需填写折扣率 | V26: 删除，映射1590
A27: JTSJCPDL201905 | B27: ICT-行业应用 | C27: JTSJCP01008 | D27: 智慧养老 | E27: 是 | F27: 户 | G27: 开通功能的用户数 | H27: 行业应用 | I27: ICT | L27: 1577 | M27: 0.06 | N27: 产业数字化-平台（大平台）-行业平台及应用-行业平台-政务行业平台应用 | O27: 1577 | P27: 产业数字化-平台（大平台）-行业平台及应用-行业平台-政务行业平台应用 | Q27: 是 | R27: 是 | S27: 无需填写速率/带宽 | T27: 无需填写折扣率 | V27: 删除，映射1577
A28: JTSJCPDL201905 | B28: ICT-行业应用 | C28: JTSJCP01009 | D28: 物流E通 | E28: 是 | F28: 户 | G28: 开通功能的用户数 | H28: 行业应用 | I28: ICT | J28: 040221 | K28: 行业应用类平台(物流E通) | L28: 1591 | M28: 0.06 | N28: 产业数字化-平台（大平台）-行业平台及应用-行业平台-交通物流平台应用 | O28: 1591 | P28: 产业数字化-平台（大平台）-行业平台及应用-行业平台-交通物流平台应用 | Q28: 是 | R28: 是 | S28: 无需填写速率/带宽 | T28: 无需填写折扣率 | V28: 删除，映射1591
A29: JTSJCPDL201905 | B29: ICT-行业应用 | C29: JTSJCP01010 | D29: 车管专家 | E29: 是 | F29: 户 | G29: 开通功能的用户数 | H29: 行业应用 | I29: ICT | J29: 040202 | K29: 行业应用类平台(车管专家) | L29: 1591 | M29: 0.06 | N29: 产业数字化-平台（大平台）-行业平台及应用-行业平台-交通物流平台应用 | O29: 1591 | P29: 产业数字化-平台（大平台）-行业平台及应用-行业平台-交通物流平台应用 | Q29: 是 | R29: 是 | S29: 无需填写速率/带宽 | T29: 无需填写折扣率 | V29: 删除，映射1591
A30: JTSJCPDL201905 | B30: ICT-行业应用 | C30: JTSJCP01011 | D30: 车载信息服务 | E30: 是 | F30: 户 | G30: 开通功能的用户数 | H30: 行业应用 | I30: ICT | J30: 040202 | K30: 行业应用类平台(车管专家) | L30: 1591 | M30: 0.06 | N30: 产业数字化-平台（大平台）-行业平台及应用-行业平台-交通物流平台应用 | O30: 1591 | P30: 产业数字化-平台（大平台）-行业平台及应用-行业平台-交通物流平台应用 | Q30: 是 | R30: 是 | S30: 无需填写速率/带宽 | T30: 无需填写折扣率 | V30: 删除，映射1591
A31: JTSJCPDL201905 | B31: ICT-行业应用 | C31: JTSJCP01013 | D31: 掌上医疗-医院版 | E31: 是 | F31: 户 | G31: 开通功能的用户数 | H31: 行业应用 | I31: ICT | J31: 040225 | K31: 行业应用类平台(掌上医疗) | L31: 1580 | M31: 0.06 | N31: 产业数字化-平台（大平台）-行业平台及应用-行业平台-卫健行业平台应用 | O31: 1580 | P31: 产业数字化-平台（大平台）-行业平台及应用-行业平台-卫健行业平台应用 | Q31: 是 | R31: 是 | S31: 无需填写速率/带宽 | T31: 无需填写折扣率 | V31: 删除，映射1580
A32: JTSJCPDL201905 | B32: ICT-行业应用 | C32: JTSJCP01014 | D32: 掌上医疗-基层版 | E32: 是 | F32: 户 | G32: 开通功能的用户数 | H32: 行业应用 | I32: ICT | J32: 040225 | K32: 行业应用类平台(掌上医疗) | L32: 1580 | M32: 0.06 | N32: 产业数字化-平台（大平台）-行业平台及应用-行业平台-卫健行业平台应用 | O32: 1580 | P32: 产业数字化-平台（大平台）-行业平台及应用-行业平台-卫健行业平台应用 | Q32: 是 | R32: 是 | S32: 无需填写速率/带宽 | T32: 无需填写折扣率 | V32: 删除，映射1580
A33: JTSJCPDL201905 | B33: ICT-行业应用 | C33: JTSJCP01016 | D33: 绿色军营 | E33: 是 | F33: 户 | G33: 开通功能的用户数 | H33: 行业应用 | I33: ICT | J33: 040901 | K33: 综合办公平台 | L33: 1634 | M33: 0.06 | N33: 产业数字化-平台（大平台）-行业平台及应用-行业信息化应用-安全办公（净收） | O33: 1634 | P33: 产业数字化-平台（大平台）-行业平台及应用-行业信息化应用-安全办公（净收） | Q33: 是 | R33: 是 | S33: 无需填写速率/带宽 | T33: 无需填写折扣率
A34: JTSJCPDL201905 | B34: ICT-行业应用 | C34: JTSJCP01017 | D34: 安全办公（军营型） | E34: 是 | F34: 户 | G34: 开通功能的用户数 | H34: 行业应用 | I34: ICT | J34: 040901 | K34: 综合办公平台 | L34: 1634 | M34: 0.06 | N34: 产业数字化-平台（大平台）-行业平台及应用-行业信息化应用-安全办公（净收） | O34: 1634 | P34: 产业数字化-平台（大平台）-行业平台及应用-行业信息化应用-安全办公（净收） | Q34: 是 | R34: 是 | S34: 无需填写速率/带宽 | T34: 无需填写折扣率
A35: JTSJCPDL201905 | B35: ICT-行业应用 | C35: JTSJCP01018 | D35: 外勤助手（定位调度） | E35: 是 | F35: 户 | G35: 开通功能的用户数 | H35: 行业应用 | I35: ICT | J35: 040217 | K35: 行业应用类平台(外勤助手) | L35: 1625 | M35: 0.06 | N35: 产业数字化-平台（大平台）-行业平台及应用-行业信息化应用-外勤助手（净收） | O35: 1625 | P35: 产业数字化-平台（大平台）-行业平台及应用-行业信息化应用-外勤助手（净收） | Q35: 是 | R35: 是 | S35: 无需填写速率/带宽 | T35: 无需填写折扣率
A36: JTSJCPDL201905 | B36: ICT-行业应用 | C36: JTSJCP01019 | D36: 天翼对讲 | E36: 是 | F36: 户 | G36: 开通功能的用户数 | H36: 行业应用 | I36: ICT | J36: 040401 | K36: 天翼对讲平台 | L36: 1622 | M36: 0.06 | N36: 产业数字化-平台（大平台）-行业平台及应用-行业信息化应用-天翼对讲（净收） | O36: 1622 | P36: 产业数字化-平台（大平台）-行业平台及应用-行业信息化应用-天翼对讲（净收） | Q36: 是 | R36: 是 | S36: 无需填写速率/带宽 | T36: 无需填写折扣率
A37: JTSJCPDL201905 | B37: ICT-行业应用 | C37: JTSJCP01020 | D37: 天翼对讲可视化调度 | E37: 是 | F37: 户 | G37: 开通功能的用户数 | H37: 行业应用 | I37: ICT | J37: 040401 | K37: 天翼对讲平台 | L37: 1622 | M37: 0.06 | N37: 产业数字化-平台（大平台）-行业平台及应用-行业信息化应用-天翼对讲（净收） | O37: 1622 | P37: 产业数字化-平台（大平台）-行业平台及应用-行业信息化应用-天翼对讲（净收） | Q37: 是 | R37: 是 | S37: 无需填写速率/带宽 | T37: 无需填写折扣率
A38: JTSJCPDL201905 | B38: ICT-行业应用 | C38: JTSJCP01021 | D38: 综合办公（移动平移） | E38: 是 | F38: 户 | G38: 开通功能的用户数 | H38: 行业应用 | I38: ICT | J38: 040901 | K38: 综合办公平台 | L38: 1628 | M38: 0.06 | N38: 产业数字化-平台（大平台）-行业平台及应用-行业信息化应用-综合办公（净收） | O38: 1628 | P38: 产业数字化-平台（大平台）-行业平台及应用-行业信息化应用-综合办公（净收） | Q38: 是 | R38: 是 | S38: 无需填写速率/带宽 | T38: 无需填写折扣率
A39: JTSJCPDL201905 | B39: ICT-行业应用 | C39: JTSJCP01022 | D39: NFC（手机钱包） | E39: 是 | F39: 户 | G39: 开通功能的用户数 | H39: 行业应用 | I39: ICT | J39: 040901 | K39: 综合办公平台 | L39: 2848 | M39: 0.06 | N39: 产业数字化-平台（大平台）-行业平台及应用-行业平台-其他 | O39: 2848 | P39: 产业数字化-平台（大平台）-行业平台及应用-行业平台-其他 | Q39: 是 | R39: 是 | S39: 无需填写速率/带宽 | T39: 无需填写折扣率 | V39: 删除，映射2848
A40: JTSJCPDL201905 | B40: ICT-行业应用 | C40: JTSJCP01023 | D40: 在线培训 | E40: 是 | F40: 户 | G40: 开通功能的用户数 | H40: 行业应用 | I40: ICT | J40: 020601 | K40: 在线培训服务平台 | L40: 2443 | M40: 0.06 | N40: 产业数字化-平台（大平台）-行业平台及应用-行业信息化应用-其他 | O40: 2443 | P40: 产业数字化-平台（大平台）-行业平台及应用-行业信息化应用-其他 | Q40: 是 | R40: 是 | S40: 无需填写速率/带宽 | T40: 无需填写折扣率 | V40: 删除，映射2443
...

Sheet 税率配置表&利润中心
A1: 指标编码 | B1: 指标名称 | C1: 税率 | D1: 税目（默认带出） | G1: 利润中心
A2: 1002 | B2: 移动通信服务-移动语音-月租费收入 | C2: 0.06 | D2: 网络元素使用服务 | G2: 上海电信EDI分公司
A3: 1005 | B3: 移动通信服务-移动语音-语音收入 | C3: 0.06 | D3: 语音服务 | G3: 总部部门
A4: 1105 | B4: 移动通信服务-手机上网-移动数据结算-网间结算-移动数据国际漫游结算 | C4: 0.06 | D4: 互联网接入服务 | G4: 工程建设中心
A5: 1106 | B5: 移动通信服务-手机上网-移动数据结算-网间结算-移动数据港台地区漫游结算 | C5: 0.06 | D5: 互联网接入服务 | G5: 渠道运营支撑中心（待迁移）
A6: 1107 | B6: 移动通信服务-手机上网-移动数据结算-网间结算-移动数据澳门地区漫游结算 | C6: 0.06 | D6: 互联网接入服务 | G6: 云网运营部
A7: 1120 | B7: 移动通信服务-移动信息化应用-个人云产品-天翼云盘 | C7: 0.06 | D7: 电子数据和信息的传输及应用服务 | G7: 政企事业群
A8: 1153 | B8: 移动通信服务-移动信息化应用-个人内容业务-合作权益收入-CP/SP结算支出 | C8: 0.06 | D8: 其他权益性无形资产 | G8: 南区局分公司
A9: 1197 | B9: 移动通信服务-其他移动通信服务-无线宽带收入 | C9: 0.06 | D9: 互联网接入服务 | G9: 东区局分公司
A10: 1204 | B10: 移动通信服务-其他移动通信服务-移动通信网络资源服务收入-移动通信设备共享服务收入-机房及配套资源合作收入 | C10: 9%;5% | D10: 不动产融资租赁（9%） | G10: 西区局分公司
A11: 1205 | B11: 移动通信服务-其他移动通信服务-移动通信网络资源服务收入-移动通信设备共享服务收入-传输线路资源合作收入 | C11: 0.09 | D11: 网络元素使用服务 | G11: 中区局分公司
A12: 1206 | B12: 移动通信服务-其他移动通信服务-移动通信网络资源服务收入-移动通信设备共享服务收入-其他共享合作收入 | C12: 0.09 | D12: 网络元素使用服务 | G12: 北区局分公司
A13: 1208 | B13: 移动通信服务-其他移动通信服务-移动通信网络资源服务收入-移动其他网络资源服务收入 | C13: 0.06 | D13: 网络元素使用服务 | G13: 宝山局分公司
A14: 2700 | B14: 移动通信服务-其他移动通信服务-移动通信网络资源服务收入-移动网络能力共享服务收入-4G移动网络能力共享服务收入 | C14: 0.06 | D14: 网络元素使用服务 | G14: 莘闵局分公司
A15: 2701 | B15: 移动通信服务-其他移动通信服务-移动通信网络资源服务收入-移动网络能力共享服务收入-其他 | C15: 0.06 | D15: 网络元素使用服务 | G15: 松江局分公司
A16: 1221 | B16: 固网及智慧家庭服务-固定电话-固网语音 | C16: 0.06 | D16: 语音服务 | G16: 奉贤局分公司
A17: 1223 | B17: 固网及智慧家庭服务-固定电话-固网语音-月租费收入 | C17: 0.06 | D17: 网络元素使用服务 | G17: 青浦局分公司
A18: 1249 | B18: 固网及智慧家庭服务-固定电话-固网增值业务 | C18: 0.06 | D18: 网络元素使用服务 | G18: 金山局分公司
A19: 2734 | B19: 固网及智慧家庭服务-固定电话-固网增值业务-其他-收入（大收） | C19: 0.06 | D19: 电子数据和信息的传输及应用服务 | G19: 移互部/移动网优中心/上海5G共建共享工作组
A20: 2735 | B20: 固网及智慧家庭服务-固定电话-固网增值业务-其他-CP/SP结算支出 | C20: 0.06 | D20: 电子数据和信息的传输及应用服务 | G20: 崇明局分公司
A21: 1289 | B21: 固网及智慧家庭服务-固定电话-固话信息产品及增值服务-企业总机-收入（大收） | C21: 0.06 | D21: 电子数据和信息的传输及应用服务 | G21: 信网部/互联网大客户部
A22: 1290 | B22: 固网及智慧家庭服务-固定电话-固话信息产品及增值服务-企业总机-CP/SP结算支出 | C22: 0.06 | D22: 电子数据和信息的传输及应用服务 | G22: 互联网部/数字生活部
... A65: 1405 | B65: 固网及智慧家庭服务-其他固网通信服务-固网通信网络资源服务收入-光纤、管孔、管道出租 | C65: 0.13 | D65: 有形动产经营租赁（13%） | G65: 科创大客户部
A66: 1408 | B66: 固网及智慧家庭服务-其他固网通信服务-固网通信网络资源服务收入-通信设备共享服务收入-机房及配套资源合作收入 | C66: 9%;5% | D66: 不动产融资租赁（9%）
A67: 1409 | B67: 固网及智慧家庭服务-其他固网通信服务-固网通信网络资源服务收入-通信设备共享服务收入-传输线路资源合作收入 | C67: 0.09 | D67: 网络元素使用服务
A68: 1410 | B68: 固网及智慧家庭服务-其他固网通信服务-固网通信网络资源服务收入-通信设备共享服务收入-国际海缆资源合作收入 | C68: 0.09 | D68: 网络元素使用服务
A69: 1411 | B69: 固网及智慧家庭服务-其他固网通信服务-固网通信网络资源服务收入-通信设备共享服务收入-云网融合合作收入 | C69: 0.09 | D69: 网络元素使用服务
A70: 1412 | B70: 固网及智慧家庭服务-其他固网通信服务-固网通信网络资源服务收入-通信设备共享服务收入-其他共享合作收入 | C70: 0.09 | D70: 网络元素使用服务
A71: 1413 | B71: 固网及智慧家庭服务-其他固网通信服务-固网通信网络资源服务收入-固网网络能力共享服务收入 | C71: 0.06 | D71: 网络元素使用服务
A72: 1414 | B72: 固网及智慧家庭服务-其他固网通信服务-固网通信网络资源服务收入-固网其他网络资源服务收入 | C72: 0.13 | D72: 网络元素使用服务
A73: 1417 | B73: 固网及智慧家庭服务-其他固网通信服务-互联网类信息服务（净收）-收入（大收） | C73: 0.06 | D73: 电子数据和信息的传输及应用服务
A74: 1418 | B74: 固网及智慧家庭服务-其他固网通信服务-互联网类信息服务（净收）-CP/SP结算支出 | C74: 0.06 | D74: 电子数据和信息的传输及应用服务
A75: 2693 | B75: 产业数字化-行业云产品-标品销售公有云产品-IaaS-计算服务-通用云主机 | C75: 0.06 | D75: 信息系统服务
A76: 2694 | B76: 产业数字化-行业云产品-标品销售公有云产品-IaaS-计算服务-智算云主机 | C76: 0.06 | D76: 信息系统服务
A77: 2695 | B77: 产业数字化-行业云产品-标品销售公有云产品-IaaS-计算服务-超算云主机 | C77: 0.06 | D77: 信息系统服务
A78: 2333 | B78: 产业数字化-行业云产品-标品销售公有云产品-IaaS-计算服务-合营云主机 | C78: 0.06 | D78: 信息系统服务
... A459: 1751 | B459: 其他-固网其他-集中服务收入 | C459: 0.09 | D459: 人力资源服务（6%）
A460: 1761 | B460: 其他-固网其他-融资出租设备收入 | C460: 13%;3% | D460: 有形动产融资租赁（13%）
A461: 1762 | B461: 其他-固网其他-出让外购软件使用权收入 | C461: 0.06 | D461: 销售无形资产
A462: 1763 | B462: 其他-固网其他-出租房产场地收入 | C462: 9%;5% | D462: 不动产融资租赁（9%）
...
