Workbook
Name 时点法: 【2026年】前向收入合同审签表!#REF!
Name 时段法: 【2026年】前向收入合同审签表!#REF!

Sheet 【2026年】前向收入合同审签表
A1: 前向收入合同审签表（2026）
A2: 收入确认计划 | B2: 必填 | C2: 选择填列 | D2: 必选 | E2: 自动带出 可修改 | F2: 自动带出 | G2: 选择填列 | H2: 自动带出 | I2: 选择填列 | J2: 自动带出 | K2: 必填 | L2: 选择填列 | M2: 自动带出 | N2: 自动带出 | O2: 自动带出 可修改 | P2: 收入确认计划 | Q2: 必填 | R2: 必填 | S2: 必选 | T2: 自动带出 可修改 | U2: 自动带出 | V2: 选择填列 | W2: 自动带出 | X2: 选择填列 | Y2: 自动带出 | Z2: 必填 | AA2: 必填 | AB2: 必填 | AC2: 公式自动算出 | AD2: 自动带出 | AE2: 自动带出 | AF2: 自动带出 可修改
A3: 非周期性 序号 | B3: 业务模式与列收方式 | C3: 预计确认日期 YYYY-MM-DD | D3: 集团产品名称 | E3: 集团产品收入项 | F3: 速率/带宽 填写提示 （在G列）→ | G3: 速率/带宽 收入项为电路及专线必填 | H3: 折扣率 填写提示 （在I列）→ | I3: 折扣率 物联网卡必填 | J3: 税率 | K3: 计划确认总金额 (含税) | L3: 填列跨省省份名称 按分摊金额分开填列 跨省电路业务必填 | M3: 业务收入对象分类 标品不触发应收任务单 | N3: 是否 网元开通 | O3: 是否CRM 确认收入 | P3: 周期性 序号 | Q3: 业务模式与列收方式 | R3: 起始日期 YYYY-MM-DD | S3: 集团产品名称 | T3: 集团产品收入项 | U3: 速率/带宽 填写提示 (在T列）→ | V3: 速率/带宽 收入项为电路及专线必填 | W3: 折扣率 填写提示 (在V列）→ | X3: 折扣率 物联网卡必填 | Y3: 税率 | Z3: 收入确认 总时长 （月） | AA3: 每月单价 | AB3: 产品数量 | AC3: 确认总金额 (含税) | AD3: 业务收入对象分类 标品不触发应收任务单 | AE3: 是否 网元开通 | AF3: 是否CRM 确认收入
A4: 1 | B4: 服务整合、总额法、时点法 | D4: MSTP-本地电路 | E4: =IFERROR(VLOOKUP(D4,【2026年】集团产品与集团产品收入项配置表!D:M,10,FALSE),"选择集团产品名称后自动带出") -> 3059(标）、3092(项) | F4: =IFERROR(VLOOKUP(D4,【2026年】集团产品与集团产品收入项配置表!D:T,17,FALSE),"选择集团产品名称后自动带出") -> 需填写速率/带宽 | H4: =IFERROR(VLOOKUP(D4,【2026年】集团产品与集团产品收入项配置表!D:U,18,FALSE),"选择集团产品名称后自动带出") -> 无需填写折扣率 | J4: =IFERROR(VLOOKUP(D4,【2026年】集团产品与集团产品收入项配置表!D:N,11,FALSE),"选择集团产品名称后自动带出") -> 0.09 | M4: =IFERROR(VLOOKUP(D4,【2026年】集团产品与集团产品收入项配置表!D:F,3,FALSE),"选择集团产品名称后自动带出") -> 标品 | N4: =IFERROR(VLOOKUP(D4,【2026年】集团产品与集团产品收入项配置表!D:R,15,FALSE),"选择集团产品名称后自动带出") -> 是 | O4: =IFERROR(VLOOKUP(D4,【2026年】集团产品与集团产品收入项配置表!D:S,16,FALSE),"选择集团产品名称后自动带出") -> 是 | P4: 1 | Q4: 服务整合、总额法、时段法 | S4: MSTP-本地电路 | T4: =IFERROR(VLOOKUP(S4,【2026年】集团产品与集团产品收入项配置表!D:M,10,FALSE),"选择集团产品名称后自动带出") -> 3059(标）、3092(项) | U4: =IFERROR(VLOOKUP(S4,【2026年】集团产品与集团产品收入项配置表!D:T,17,FALSE),"选择集团产品名称后自动带出") -> 需填写速率/带宽 | W4: =IFERROR(VLOOKUP(S4,【2026年】集团产品与集团产品收入项配置表!D:U,18,FALSE),"选择集团产品名称后自动带出") -> 无需填写折扣率 | Y4: =IFERROR(VLOOKUP(S4,【2026年】集团产品与集团产品收入项配置表!D:N,11,FALSE),"选择集团产品名称后自动带出") -> 0.09 | AC4: =AA4*AB4*Z4 -> 0 | AD4: =IFERROR(VLOOKUP(S4,【2026年】集团产品与集团产品收入项配置表!D:F,3,FALSE),"选择集团产品名称后自动带出") -> 标品 | AE4: =IFERROR(VLOOKUP(S4,【2026年】集团产品与集团产品收入项配置表!D:R,15,FALSE),"选择集团产品名称后自动带出") -> 是 | AF4: =IFERROR(VLOOKUP(S4,【2026年】集团产品与集团产品收入项配置表!D:S,16,FALSE),"选择集团产品名称后自动带出") -> 是
A5: 2 | E5: =IFERROR(VLOOKUP(D5,【2026年】集团产品与集团产品收入项配置表!D:M,10,FALSE),"选择集团产品名称后自动带出") -> 选择集团产品名称后自动带出 | F5: =IFERROR(VLOOKUP(D5,【2026年】集团产品与集团产品收入项配置表!D:T,17,FALSE),"选择集团产品名称后自动带出") -> 选择集团产品名称后自动带出 | H5: =IFERROR(VLOOKUP(D5,【2026年】集团产品与集团产品收入项配置表!D:U,18,FALSE),"选择集团产品名称后自动带出") -> 选择集团产品名称后自动带出 | J5: =IFERROR(VLOOKUP(D5,【2026年】集团产品与集团产品收入项配置表!D:N,11,FALSE),"选择集团产品名称后自动带出") -> 选择集团产品名称后自动带出 | M5: =IFERROR(VLOOKUP(D5,【2026年】集团产品与集团产品收入项配置表!D:F,3,FALSE),"选择集团产品名称后自动带出") -> 选择集团产品名称后自动带出 | N5: =IFERROR(VLOOKUP(D5,【2026年】集团产品与集团产品收入项配置表!D:R,15,FALSE),"选择集团产品名称后自动带出") -> 选择集团产品名称后自动带出 | O5: =IFERROR(VLOOKUP(D5,【2026年】集团产品与集团产品收入项配置表!D:S,16,FALSE),"选择集团产品名称后自动带出") -> 选择集团产品名称后自动带出 | P5: 2 | T5: =IFERROR(VLOOKUP(S5,【2026年】集团产品与集团产品收入项配置表!D:M,10,FALSE),"选择集团产品名称后自动带出") -> 选择集团产品名称后自动带出 | U5: =IFERROR(VLOOKUP(S5,【2026年】集团产品与集团产品收入项配置表!D:T,17,FALSE),"选择集团产品名称后自动带出") -> 选择集团产品名称后自动带出 | W5: =IFERROR(VLOOKUP(S5,【2026年】集团产品与集团产品收入项配置表!D:U,18,FALSE),"选择集团产品名称后自动带出") -> 选择集团产品名称后自动带出 | Y5: =IFERROR(VLOOKUP(S5,【2026年】集团产品与集团产品收入项配置表!D:N,11,FALSE),"选择集团产品名称后自动带出") -> 选择集团产品名称后自动带出 | AC5: =AA5*AB5*Z5 -> 0 | AD5: =IFERROR(VLOOKUP(S5,【2026年】集团产品与集团产品收入项配置表!D:F,3,FALSE),"选择集团产品名称后自动带出") -> 选择集团产品名称后自动带出 | AE5: =IFERROR(VLOOKUP(S5,【2026年】集团产品与集团产品收入项配置表!D:R,15,FALSE),"选择集团产品名称后自动带出") -> 选择集团产品名称后自动带出 | AF5: =IFERROR(VLOOKUP(S5,【2026年】集团产品与集团产品收入项配置表!D:S,16,FALSE),"选择集团产品名称后自动带出") -> 选择集团产品名称后自动带出
A6: 3 | E6: =IFERROR(VLOOKUP(D6,【2026年】集团产品与集团产品收入项配置表!D:M,10,FALSE),"选择集团产品名称后自动带出") -> 选择集团产品名称后自动带出 | F6: =IFERROR(VLOOKUP(D6,【2026年】集团产品与集团产品收入项配置表!D:T,17,FALSE),"选择集团产品名称后自动带出") -> 选择集团产品名称后自动带出 | H6: =IFERROR(VLOOKUP(D6,【2026年】集团产品与集团产品收入项配置表!D:U,18,FALSE),"选择集团产品名称后自动带出") -> 选择集团产品名称后自动带出 | J6: =IFERROR(VLOOKUP(D6,【2026年】集团产品与集团产品收入项配置表!D:N,11,FALSE),"选择集团产品名称后自动带出") -> 选择集团产品名称后自动带出 | M6: =IFERROR(VLOOKUP(D6,【2026年】集团产品与集团产品收入项配置表!D:F,3,FALSE),"选择集团产品名称后自动带出") -> 选择集团产品名称后自动带出 | N6: =IFERROR(VLOOKUP(D6,【2026年】集团产品与集团产品收入项配置表!D:R,15,FALSE),"选择集团产品名称后自动带出") -> 选择集团产品名称后自动带出 | O6: =IFERROR(VLOOKUP(D6,【2026年】集团产品与集团产品收入项配置表!D:S,16,FALSE),"选择集团产品名称后自动带出") -> 选择集团产品名称后自动带出 | P6: 3 | T6: =IFERROR(VLOOKUP(S6,【2026年】集团产品与集团产品收入项配置表!D:M,10,FALSE),"选择集团产品名称后自动带出") -> 选择集团产品名称后自动带出 | U6: =IFERROR(VLOOKUP(S6,【2026年】集团产品与集团产品收入项配置表!D:T,17,FALSE),"选择集团产品名称后自动带出") -> 选择集团产品名称后自动带出 | W6: =IFERROR(VLOOKUP(S6,【2026年】集团产品与集团产品收入项配置表!D:U,18,FALSE),"选择集团产品名称后自动带出") -> 选择集团产品名称后自动带出 | Y6: =IFERROR(VLOOKUP(S6,【2026年】集团产品与集团产品收入项配置表!D:N,11,FALSE),"选择集团产品名称后自动带出") -> 选择集团产品名称后自动带出 | AC6: =AA6*AB6*Z6 -> 0 | AD6: =IFERROR(VLOOKUP(S6,【2026年】集团产品与集团产品收入项配置表!D:F,3,FALSE),"选择集团产品名称后自动带出") -> 选择集团产品名称后自动带出 | AE6: =IFERROR(VLOOKUP(S6,【2026年】集团产品与集团产品收入项配置表!D:R,15,FALSE),"选择集团产品名称后自动带出") -> 选择集团产品名称后自动带出 | AF6: =IFERROR(VLOOKUP(S6,【2026年】集团产品与集团产品收入项配置表!D:S,16,FALSE),"选择集团产品名称后自动带出") -> 选择集团产品名称后自动带出
A7: 4 | E7: =IFERROR(VLOOKUP(D7,【2026年】集团产品与集团产品收入项配置表!D:M,10,FALSE),"选择集团产品名称后自动带出") -> 选择集团产品名称后自动带出 | F7: =IFERROR(VLOOKUP(D7,【2026年】集团产品与集团产品收入项配置表!D:T,17,FALSE),"选择集团产品名称后自动带出") -> 选择集团产品名称后自动带出 | H7: =IFERROR(VLOOKUP(D7,【2026年】集团产品与集团产品收入项配置表!D:U,18,FALSE),"选择集团产品名称后自动带出") -> 选择集团产品名称后自动带出 | J7: =IFERROR(VLOOKUP(D7,【2026年】集团产品与集团产品收入项配置表!D:N,11,FALSE),"选择集团产品名称后自动带出") -> 选择集团产品名称后自动带出 | M7: =IFERROR(VLOOKUP(D7,【2026年】集团产品与集团产品收入项配置表!D:F,3,FALSE),"选择集团产品名称后自动带出") -> 选择集团产品名称后自动带出 | N7: =IFERROR(VLOOKUP(D7,【2026年】集团产品与集团产品收入项配置表!D:R,15,FALSE),"选择集团产品名称后自动带出") -> 选择集团产品名称后自动带出 | O7: =IFERROR(VLOOKUP(D7,【2026年】集团产品与集团产品收入项配置表!D:S,16,FALSE),"选择集团产品名称后自动带出") -> 选择集团产品名称后自动带出 | P7: 4 | T7: =IFERROR(VLOOKUP(S7,【2026年】集团产品与集团产品收入项配置表!D:M,10,FALSE),"选择集团产品名称后自动带出") -> 选择集团产品名称后自动带出 | U7: =IFERROR(VLOOKUP(S7,【2026年】集团产品与集团产品收入项配置表!D:T,17,FALSE),"选择集团产品名称后自动带出") -> 选择集团产品名称后自动带出 | W7: =IFERROR(VLOOKUP(S7,【2026年】集团产品与集团产品收入项配置表!D:U,18,FALSE),"选择集团产品名称后自动带出") -> 选择集团产品名称后自动带出 | Y7: =IFERROR(VLOOKUP(S7,【2026年】集团产品与集团产品收入项配置表!D:N,11,FALSE),"选择集团产品名称后自动带出") -> 选择集团产品名称后自动带出 | AC7: =AA7*AB7*Z7 -> 0 | AD7: =IFERROR(VLOOKUP(S7,【2026年】集团产品与集团产品收入项配置表!D:F,3,FALSE),"选择集团产品名称后自动带出") -> 选择集团产品名称后自动带出 | AE7: =IFERROR(VLOOKUP(S7,【2026年】集团产品与集团产品收入项配置表!D:R,15,FALSE),"选择集团产品名称后自动带出") -> 选择集团产品名称后自动带出 | AF7: =IFERROR(VLOOKUP(S7,【2026年】集团产品与集团产品收入项配置表!D:S,16,FALSE),"选择集团产品名称后自动带出") -> 选择集团产品名称后自动带出
A8: 5 | E8: =IFERROR(VLOOKUP(D8,【2026年】集团产品与集团产品收入项配置表!D:M,10,FALSE),"选择集团产品名称后自动带出") -> 选择集团产品名称后自动带出 | F8: =IFERROR(VLOOKUP(D8,【2026年】集团产品与集团产品收入项配置表!D:T,17,FALSE),"选择集团产品名称后自动带出") -> 选择集团产品名称后自动带出 | H8: =IFERROR(VLOOKUP(D8,【2026年】集团产品与集团产品收入项配置表!D:U,18,FALSE),"选择集团产品名称后自动带出") -> 选择集团产品名称后自动带出 | J8: =IFERROR(VLOOKUP(D8,【2026年】集团产品与集团产品收入项配置表!D:N,11,FALSE),"选择集团产品名称后自动带出") -> 选择集团产品名称后自动带出 | M8: =IFERROR(VLOOKUP(D8,【2026年】集团产品与集团产品收入项配置表!D:F,3,FALSE),"选择集团产品名称后自动带出") -> 选择集团产品名称后自动带出 | N8: =IFERROR(VLOOKUP(D8,【2026年】集团产品与集团产品收入项配置表!D:R,15,FALSE),"选择集团产品名称后自动带出") -> 选择集团产品名称后自动带出 | O8: =IFERROR(VLOOKUP(D8,【2026年】集团产品与集团产品收入项配置表!D:S,16,FALSE),"选择集团产品名称后自动带出") -> 选择集团产品名称后自动带出 | P8: 5 | T8: =IFERROR(VLOOKUP(S8,【2026年】集团产品与集团产品收入项配置表!D:M,10,FALSE),"选择集团产品名称后自动带出") -> 选择集团产品名称后自动带出 | U8: =IFERROR(VLOOKUP(S8,【2026年】集团产品与集团产品收入项配置表!D:T,17,FALSE),"选择集团产品名称后自动带出") -> 选择集团产品名称后自动带出 | W8: =IFERROR(VLOOKUP(S8,【2026年】集团产品与集团产品收入项配置表!D:U,18,FALSE),"选择集团产品名称后自动带出") -> 选择集团产品名称后自动带出 | Y8: =IFERROR(VLOOKUP(S8,【2026年】集团产品与集团产品收入项配置表!D:N,11,FALSE),"选择集团产品名称后自动带出") -> 选择集团产品名称后自动带出 | AC8: =AA8*AB8*Z8 -> 0 | AD8: =IFERROR(VLOOKUP(S8,【2026年】集团产品与集团产品收入项配置表!D:F,3,FALSE),"选择集团产品名称后自动带出") -> 选择集团产品名称后自动带出 | AE8: =IFERROR(VLOOKUP(S8,【2026年】集团产品与集团产品收入项配置表!D:R,15,FALSE),"选择集团产品名称后自动带出") -> 选择集团产品名称后自动带出 | AF8: =IFERROR(VLOOKUP(S8,【2026年】集团产品与集团产品收入项配置表!D:S,16,FALSE),"选择集团产品名称后自动带出") -> 选择集团产品名称后自动带出
A9: 合 计 | K9: =SUM(K4:K8) -> 0 | P9: 合 计 | AC9: =SUM(AC4:AC8) -> 0
A11: 是否有 履约保证金 | C11: 是否有 维保要求 | E11: 是否有 审计条款 | G11: 发票种类 （必选） | H11: 增值税专用发票 | I11: 该合同实际 利润归属单位 （必选） | J11: 智慧商务部/号百公司
A13: 收款计划 | B13: 必填 | C13: 必选 | D13: 必填 | E13: 必选 | F13: 按比例收款 时必填 | G13: 必填 | H13: 必选 | I13: 收款计划 | J13: 必填 | K13: 必选 | L13: 必填 | M13: 必填 | N13: 公式自动算出 | O13: 必选
A14: 非周期性 序号 | B14: 预计收款日期 YYYY-MM-DD | C14: 非周期 收款方式 | D14: 第N次 | E14: 履行要求 | F14: 约定收款 比例 | G14: 约定收款 金额 | H14: 收款 触发系统 | I14: 周期性 序号 | J14: 预计收款 起始日期 YYYY-MM-DD | K14: 收款频率 （周期方式） | L14: 期数 | M14: 每期金额 | N14: 金额合计 | O14: 收款 触发系统
A15: 1 | I15: 1 | N15: =L15*M15 -> 0
A16: 2 | I16: 2 | N16: =L16*M16 -> 0
A17: 3 | I17: 3 | N17: =L17*M17 -> 0
A18: 4 | I18: 4 | N18: =L18*M18 -> 0
A19: 5 | I19: 5 | N19: =L19*M19 -> 0
A20: 合 计 | F20: =SUM(F15:F19) -> 0 | G20: =SUM(G15:G19) -> 0 | I20: 合 计 | N20: =SUM(N15:N19) -> 0
A22: 填表人： （必填） | B22: 王照龙 | C22: 联系方式： （必填） | D22: 02152927531 | E22: 项目立项人: （必填） | F22: 王照龙 | G22: 联系方式： （必填） | H22: 02152927531
A25: 填表说明：
A26: 1、若涉及多项产品收入项的请分行填列，小计金额需与合同金额一致。
A27: 2、若合同履约信息即有非周期性也有周期性，则在相应表格中填列。
A28: 3、若该合同有跨利润中心的情况，请填列“该合同实际利润归属单位”信息，不然合同解析利润中心默认为合同发起单位。
A29: 4、若非周期收款方式为按金额收款的，表格中约定收款比例可不填列。
A30: 5、“是否有履约保证金”、“是否有维保要求”及“是否有审计条款”默认为“否”，若该合同涉及此3项有实际发生的请改为“是”并附相应情况说明。
A31: 6、由于目前部分产品较个性化，不具备标准化资费的条件，无法走CRM系统开账，而通过聚焦系统开账会虚增应收账款，因此选“非CRM确认收入”的合同，其实际履约信息若为周期性的，一律解析为非周期性。
A32: 7、集团要求按月确认收入的为收入周期性，除此之外均为非周期性收入；而收款方式的频率若为按月、按季、按半年、按年则均为周期性收款。
A33: 8、集团要求涉及电路及专线类收入项的话，速率及带宽为必填，涉及物联网收入项的话，折扣率为必填。
A34: 9、跨省电路业务新增“跨省省份”列，请按分摊金额分开填列。

Sheet 【2026年】集团产品与集团产品收入项配置表
A1: 产品大类编码（修订） | B1: 产品大类（修订） | C1: 产品编码 | D1: 产品名称 | E1: 是否ICT产品 | F1: 是否标品 | G1: 单位 | H1: 注释 | I1: 产品类型 | J1: 产品类别 | K1: 平台类型编码 | L1: 平台类型 名称 | M1: 默认带出的产品收入项2026 | N1: 税率 | O1: 默认带出的产品收入项名称2026 （ICT合同中含IDC、组网专线、物联网、5G定制网内容需调整为“项目型”） | P1: 可选产品收入项范围编码2026 | Q1: 可选产品收入项范围2026 | R1: 是否网元 | S1: 是否触发CRM | T1: 速率/带宽 填写提示 | U1: 折扣率 填写提示
A2: JTSJCPDL201915 | B2: 云网融合业务 | C2: JTSJCP02222 | D2: 教育专网（统筹省级） | E2: 是 | F2: 标品 | I2: 云业务 | J2: ICT | L2: 专线接入成本 | M2: 3077(标）、3110(项) | N2: 0.09 | O2: 产业数字化-资源型服务-组网专线-标品型-普通组网专线-普通组网专线-其他 | P2: 3077 | Q2: 产业数字化-资源型服务-组网专线-标品型-普通组网专线-其他 | R2: 是 | S2: 是 | T2: 需填写速率/带宽 | U2: 无需填写折扣率
A3: JTSJCPDL201915 | B3: 云网融合业务 | C3: JTSJCP02223 | D3: FIRST金融专网 | E3: 是 | F3: 标品 | I3: 云业务 | J3: ICT | L3: 专线接入成本 | M3: 3077(标）、3110(项) | N3: 0.09 | O3: 产业数字化-资源型服务-组网专线-标品型-普通组网专线-普通组网专线-其他 | P3: 3077 | Q3: 产业数字化-资源型服务-组网专线-标品型-普通组网专线-其他 | R3: 是 | S3: 是 | T3: 需填写速率/带宽 | U3: 无需填写折扣率
A4: JTSJCPDL201915 | B4: 云网融合业务 | C4: JTSJCP02225 | D4: 视频专网（统筹省级） | E4: 是 | F4: 标品 | I4: 云业务 | J4: ICT | L4: 专线接入成本 | M4: 3077(标）、3110(项) | N4: 0.09 | O4: 产业数字化-资源型服务-组网专线-标品型-普通组网专线-普通组网专线-其他 | P4: 3077 | Q4: 产业数字化-资源型服务-组网专线-标品型-普通组网专线-其他 | R4: 是 | S4: 是 | T4: 需填写速率/带宽 | U4: 无需填写折扣率
A5: JTSJCPDL201915 | B5: 云网融合业务 | C5: JTSJCP02227 | D5: 云专网 | E5: 是 | F5: 标品 | I5: 云业务 | J5: ICT | L5: 专线接入成本 | M5: 3077(标）、3110(项) | N5: 0.09 | O5: 产业数字化-资源型服务-组网专线-标品型-普通组网专线-普通组网专线-其他 | P5: 3077 | Q5: 产业数字化-资源型服务-组网专线-标品型-普通组网专线-其他 | R5: 是 | S5: 是 | T5: 需填写速率/带宽 | U5: 无需填写折扣率
A6: JTSJCPDL201915 | B6: 云网融合业务 | C6: JTSJCP02226 | D6: 物联专网（统筹省级） | E6: 是 | F6: 标品 | I6: 云业务 | J6: ICT | L6: 专线接入成本 | M6: 2891 | N6: 0.06 | O6: 产业数字化-资源型服务-物联网-项目型物联网-其他 | P6: 2891 | Q6: 产业数字化-资源型服务-物联网-项目型物联网-其他 | R6: 是 | S6: 是 | T6: 需填写速率/带宽 | U6: 无需填写折扣率
A7: JTSJCPDL201915 | B7: 云网融合业务 | C7: JTSJCP02228 | D7: 智能专线 | E7: 是 | F7: 标品 | I7: 云业务 | J7: ICT | L7: 专线接入成本 | M7: 2967 | N7: 0.06 | O7: 产业数字化-ICT业务-行业云产品-项目中公有云产品-IaaS-云网服务-其他-自研 | P7: 2967 | Q7: 产业数字化-ICT业务-行业云产品-项目中公有云产品-IaaS-云网服务-其他-自研 | R7: 是 | S7: 是 | T7: 需填写速率/带宽 | U7: 无需填写折扣率
A8: JTSJCPDL201914 | B8: 其它业务 | C8: JTSJCP03007 | D8: 房地产出租 | E8: 否 | F8: 其他 | G8: - | H8: - | I8: 房屋租赁 | M8: 1763 | N8: 9%、5% | O8: 其他-固网其他-出租房产场地收入 | P8: 1763 | R8: 否 | S8: 否 | T8: 无需填写速率/带宽 | U8: 无需填写折扣率
A9: JTSJCPDL201913 | B9: 其他固网业务 | C9: JTSJCP02078 | D9: 设备出售 | E9: 否 | F9: 设备 | G9: - | H9: - | I9: 外延业务 | M9: 3212 | N9: 0.13 | O9: 其他-固网其他-实物商品销售-系统集成-其他 | P9: 3212 | Q9: 其他-固网其他-实物商品销售-系统集成-其他 | R9: 否 | S9: 否 | T9: 无需填写速率/带宽 | U9: 无需填写折扣率
A10: JTSJCPDL201913 | B10: 其他固网业务 | C10: JTSJCP02043 | D10: 普通电话 | E10: 否 | F10: 标品 | G10: 部 | H10: 电话数 | I10: 外延业务 | M10: 1221 | N10: 0.06 | O10: 固网及智慧家庭服务-固定电话-固网语音 | P10: 1221 | Q10: 固网及智慧家庭服务-固定电话-固网语音 | R10: 是 | S10: 是 | T10: 无需填写速率/带宽 | U10: 无需填写折扣率
A11: JTSJCPDL201913 | B11: 其他固网业务 | C11: JTSJCP02044 | D11: 语音中继线 | E11: 否 | F11: 标品 | G11: 条 | H11: 线路数 | I11: 外延业务 | L11: 本地SDH电路 | M11: 1221 | N11: 0.06 | O11: 固网及智慧家庭服务-固定电话-固网语音 | P11: 1221 | Q11: 固网及智慧家庭服务-固定电话-固网语音 | R11: 是 | S11: 是 | T11: 需填写速率/带宽 | U11: 无需填写折扣率
A12: JTSJCPDL201913 | B12: 其他固网业务 | C12: JTSJCP02045 | D12: ISDN | E12: 否 | F12: 标品 | G12: 条 | H12: 线路数 | I12: 外延业务 | M12: 1221 | N12: 0.06 | O12: 固网及智慧家庭服务-固定电话-固网语音 | P12: 1221 | Q12: 固网及智慧家庭服务-固定电话-固网语音 | R12: 是 | S12: 是 | T12: 无需填写速率/带宽 | U12: 无需填写折扣率
A13: JTSJCPDL201913 | B13: 其他固网业务 | C13: JTSJCP02053 | D13: 拨号上网 | E13: 否 | F13: 标品 | G13: 条 | H13: 线路数 | I13: 外延业务 | J13: 专线 | L13: ADSL终端接入 | M13: 1312 | N13: 0.06 | O13: 固网及智慧家庭服务-互联网宽带接入-普通宽带-宽带接入收入-其他 | P13: 1309;1310;1311;1312 | Q13: 固网及智慧家庭服务-互联网宽带接入-普通宽带-宽带接入收入-FTTH/O;固网及智慧家庭服务-互联网宽带接入-普通宽带-宽带接入收入-ADSL;固网及智慧家庭服务-互联网宽带接入-普通宽带-宽带接入收入-LAN;固网及智慧家庭服务-互联网宽带接入-普通宽带-宽带接入收入-其他 | R13: 是 | S13: 是 | T13: 需填写速率/带宽 | U13: 无需填写折扣率
A14: JTSJCPDL201913 | B14: 其他固网业务 | C14: JTSJCP02054 | D14: WLAN上网 | E14: 否 | F14: 标品 | G14: 条 | H14: 线路数 | I14: 外延业务 | J14: 专线 | L14: LAN终端接入 | M14: 1312 | N14: 0.06 | O14: 固网及智慧家庭服务-互联网宽带接入-普通宽带-宽带接入收入-其他 | P14: 1309;1310;1311;1312 | Q14: 固网及智慧家庭服务-互联网宽带接入-普通宽带-宽带接入收入-FTTH/O;固网及智慧家庭服务-互联网宽带接入-普通宽带-宽带接入收入-ADSL;固网及智慧家庭服务-互联网宽带接入-普通宽带-宽带接入收入-LAN;固网及智慧家庭服务-互联网宽带接入-普通宽带-宽带接入收入-其他 | R14: 是 | S14: 是 | T14: 需填写速率/带宽 | U14: 无需填写折扣率
A15: JTSJCPDL201913 | B15: 其他固网业务 | C15: JTSJCP02072 | D15: 设备租赁 | E15: 否 | F15: 设备 | G15: 台 | H15: 设备数 | I15: 外延业务 | M15: 1414 | N15: 0.06 | O15: 固网及智慧家庭服务-其他固网通信服务-固网通信网络资源服务收入-固网其他网络资源服务收入 | P15: 1414 | Q15: 固网及智慧家庭服务-其他固网通信服务-固网通信网络资源服务收入-固网其他网络资源服务收入 | R15: 否 | S15: 是 | T15: 无需填写速率/带宽 | U15: 无需填写折扣率
A16: JTSJCPDL201913 | B16: 其他固网业务 | C16: JTSJCP02073 | D16: 通信管道出租 | E16: 否 | F16: 标品 | G16: 条 | H16: 线路数 | I16: 外延业务 | J16: 电路 | M16: 1414 | N16: 0.06 | O16: 固网及智慧家庭服务-其他固网通信服务-固网通信网络资源服务收入-固网其他网络资源服务收入 | P16: 1414;3109; | Q16: 固网及智慧家庭服务-其他固网通信服务-固网通信网络资源服务收入-固网其他网络资源服务收入;产业数字化-资源型服务-组网专线-项目型组网专线-普通组网专线-国际及港澳台网元业务 | R16: 是 | S16: 是 | T16: 无需填写速率/带宽 | U16: 无需填写折扣率
A17: JTSJCPDL201913 | B17: 其他固网业务 | C17: JTSJCP02077 | D17: SI结算支出 | E17: 是 | F17: 其他 | G17: - | H17: - | I17: 行业应用 | J17: ICT | M17: 1616 | N17: 0.06 | O17: 产业数字化-ICT业务-行业平台及应用-通用信息化标品-协同通信 | P17: 1616 | Q17: 产业数字化-ICT业务-行业平台及应用-通用信息化标品-协同通信 | R17: 否 | S17: 是 | T17: 无需填写速率/带宽 | U17: 无需填写折扣率
A18: JTSJCPDL201913 | B18: 其他固网业务 | C18: JTSJCP02079 | D18: 固网其他业务 | E18: 否 | F18: 其他 | G18: - | H18: - | I18: 外延业务 | M18: 1738 | N18: 0.06 | O18: 其他-固网其他 | P18: 1738 | Q18: 其他-固网其他 | R18: 否 | S18: 是 | T18: 无需填写速率/带宽 | U18: 无需填写折扣率
A19: JTSJCPDL201913 | B19: 其他固网业务 | C19: JTSJCP02040 | D19: 爱wifi | E19: 否 | F19: 标品 | G19: 个 | H19: 热点数 | I19: 外延业务 | M19: 2735 | N19: 0.06 | O19: 固网及智慧家庭服务-固定电话-固网增值业务-其他-CP/SP结算支出 | P19: 2735 | Q19: 固网及智慧家庭服务-固定电话-固网增值业务-其他-CP/SP结算支出 | R19: 是 | S19: 是 | T19: 无需填写速率/带宽 | U19: 无需填写折扣率
A20: JTSJCPDL201912 | B20: 增值业务 | C20: JTSJCP02056 | D20: 国内4008电话 | E20: 否 | F20: 标品 | G20: 个 | H20: 号码数 | I20: 外延业务 | M20: 1221 | N20: 0.06 | O20: 固网及智慧家庭服务-固定电话-固网语音 | P20: 1221 | Q20: 固网及智慧家庭服务-固定电话-固网语音 | R20: 是 | S20: 是 | T20: 无需填写速率/带宽 | U20: 无需填写折扣率
A21: JTSJCPDL201912 | B21: 增值业务 | C21: JTSJCP03001 | D21: 行业彩信 | E21: 否 | F21: 标品 | G21: 个 | H21: 短号码数量 | I21: 外延业务 | M21: 1249 | N21: 0.06 | O21: 固网及智慧家庭服务-固定电话-固网增值业务 | P21: 1249 | Q21: 固网及智慧家庭服务-固定电话-固网增值业务 | R21: 是 | S21: 是 | T21: 无需填写速率/带宽 | U21: 无需填写折扣率
A22: JTSJCPDL201912 | B22: 增值业务 | C22: JTSJCP03002 | D22: 行业短信-普通短信 | E22: 否 | F22: 标品 | G22: 个 | H22: 短号码数量 | I22: 外延业务 | M22: 1249 | N22: 0.06 | O22: 固网及智慧家庭服务-固定电话-固网增值业务 | P22: 1249 | Q22: 固网及智慧家庭服务-固定电话-固网增值业务 | R22: 是 | S22: 是 | T22: 无需填写速率/带宽 | U22: 无需填写折扣率
A23: JTSJCPDL201912 | B23: 增值业务 | C23: JTSJCP01002 | D23: 总机服务 | E23: 否 | F23: 标品 | G23: 户 | H23: 开通功能的用户数 | I23: 外延业务 | M23: 1289 | N23: 0.06 | O23: 固网及智慧家庭服务-固定电话-企业总机-收入（大收） | P23: 1289 | Q23: 固网及智慧家庭服务-固定电话-企业总机-收入（大收） | R23: 是 | S23: 是 | T23: 无需填写速率/带宽 | U23: 无需填写折扣率
A24: JTSJCPDL201912 | B24: 增值业务 | C24: JTSJCP01046 | D24: 无线VPDN | E24: 是 | F24: 标品 | G24: 户 | H24: 开通功能的用户数 | I24: 行业应用 -250115改：外延业务 | J24: ICT-250115改：删除产品类别 | M24: 1197 | N24: 0.06 | O24: 移动通信服务-其他移动通信服务-无线宽带收入 | P24: 1197 | Q24: 移动通信服务-其他移动通信服务-无线宽带收入 | R24: 是 | S24: 是 | T24: 无需填写速率/带宽 | U24: 无需填写折扣率
A25: JTSJCPDL201912 | B25: 增值业务 | C25: JTSJCP02058 | D25: 天翼高清（集约） | E25: 否 | F25: 标品 | G25: 台 | H25: 天翼高清的台数 | I25: 外延业务 | M25: 2735 | N25: 0.06 | O25: 固网及智慧家庭服务-固定电话-固网增值业务-其他-CP/SP结算支出 | P25: 2735 | Q25: 固网及智慧家庭服务-固定电话-固网增值业务-其他-CP/SP结算支出 | R25: 是 | S25: 是 | T25: 无需填写速率/带宽 | U25: 无需填写折扣率
A26: JTSJCPDL201912 | B26: 增值业务 | C26: JTSJCP03004 | D26: 800电话 | E26: 否 | F26: 标品 | G26: G | H26: 包含的流量数 | I26: 外延业务 | M26: 1197 | N26: 0.06 | O26: 移动通信服务-其他移动通信服务-无线宽带收入 | P26: 1197 | Q26: 移动通信服务-其他移动通信服务-无线宽带收入 | R26: 是 | S26: 是 | T26: 无需填写速率/带宽 | U26: 无需填写折扣率
A27: JTSJCPDL201912 | B27: 增值业务 | C27: JTSJCP02219 | D27: 行业短信-富媒体短信 | E27: 是 | F27: 标品 | I27: 外延业务 | J27: ICT | M27: 2943 | N27: 0.06 | O27: 移动通信服务-移动信息化应用-个人云产品-天翼云盘-基础功能费 | P27: 2943;2944 | Q27: 移动通信服务-移动信息化应用-个人云产品-天翼云盘-基础功能费;移动通信服务-移动信息化应用-个人云产品-天翼云盘-会员服务费 | R27: 是 | S27: 是 | T27: 无需填写速率/带宽 | U27: 无需填写折扣率
A28: JTSJCPDL201912 | B28: 增值业务 | C28: JTSJCP02220 | D28: 行业短信-秒达短信 | E28: 是 | F28: 标品 | I28: 外延业务 | J28: ICT | M28: 2943 | N28: 0.06 | O28: 移动通信服务-移动信息化应用-个人云产品-天翼云盘-基础功能费 | P28: 2943;2944 | Q28: 移动通信服务-移动信息化应用-个人云产品-天翼云盘-基础功能费;移动通信服务-移动信息化应用-个人云产品-天翼云盘-会员服务费 | R28: 是 | S28: 是 | T28: 无需填写速率/带宽 | U28: 无需填写折扣率
A29: JTSJCPDL201912 | B29: 增值业务 | C29: JTSJCP02221 | D29: 行业短信-智能短信 | E29: 是 | F29: 标品 | I29: 外延业务 | J29: ICT | M29: 2943 | N29: 0.06 | O29: 移动通信服务-移动信息化应用-个人云产品-天翼云盘-基础功能费 | P29: 2943;2944 | Q29: 移动通信服务-移动信息化应用-个人云产品-天翼云盘-基础功能费;移动通信服务-移动信息化应用-个人云产品-天翼云盘-会员服务费 | R29: 是 | S29: 是 | T29: 无需填写速率/带宽 | U29: 无需填写折扣率
A30: JTSJCPDL201911 | B30: 基础移动业务 | C30: JTSJCP01001 | D30: 4G（LTE）上网 | E30: 否 | F30: 标品 | G30: 户 | H30: 拉动移动入网用户数 | I30: 外延业务 | K30: 040229 | L30: 移动业务户均成本 | M30: 1005 | N30: 0.06 | O30: 移动通信服务-移动语音-语音收入 | P30: 1005 | Q30: 移动通信服务-移动语音-语音收入 | R30: 是 | S30: 是 | T30: 无需填写速率/带宽 | U30: 无需填写折扣率
A31: JTSJCPDL201910 | B31: 卫星业务 | C31: JTSJCP01051 | D31: 卫星移动通信业务-语音 | E31: 否 | F31: 标品 | G31: 户 | H31: 拉动移动入网用户数 | I31: 外延业务 | J31: 专线 | M31: 1005 | N31: 0.06 | O31: 移动通信服务-移动语音-语音收入 | P31: 1005 | Q31: 移动通信服务-移动语音-语音收入 | R31: 是 | T31: 无需填写速率/带宽 | U31: 无需填写折扣率
A32: JTSJCPDL201910 | B32: 卫星业务 | C32: JTSJCP02090 | D32: 卫星宽带带宽型-国内 | E32: 否 | F32: 标品 | G32: 条 | H32: 线路数 | I32: 外延业务 | J32: 专线 | L32: 专线接入成本 | M32: 1301 | N32: 0.06 | O32: 固网及智慧家庭服务-互联网宽带接入-卫星宽带-卫星宽带服务 | P32: 1301;1302; | Q32: 固网及智慧家庭服务-互联网宽带接入-卫星宽带-卫星宽带服务;固网及智慧家庭服务-互联网宽带接入-卫星宽带-卫星资源服务 | R32: 是 | S32: 是 | T32: 需填写速率/带宽 | U32: 无需填写折扣率
A33: JTSJCPDL201910 | B33: 卫星业务 | C33: JTSJCP02051 | D33: 卫星宽带流量型（企业版） | E33: 否 | F33: 标品 | G33: 条 | H33: 线路数 | I33: 外延业务 | J33: 电路 | M33: 1301 | N33: 0.06 | O33: 固网及智慧家庭服务-互联网宽带接入-卫星宽带-卫星宽带服务 | P33: 1301;1302; | Q33: 固网及智慧家庭服务-互联网宽带接入-卫星宽带-卫星宽带服务;固网及智慧家庭服务-互联网宽带接入-卫星宽带-卫星资源服务 | R33: 是 | S33: 是 | T33: 无需填写速率/带宽 | U33: 无需填写折扣率
A34: JTSJCPDL201910 | B34: 卫星业务 | C34: JTSJCP02052 | D34: 卫星宽带带宽型-国际 | E34: 否 | F34: 标品 | G34: 条 | H34: 线路数 | I34: 外延业务 | J34: 专线 | L34: 专线接入成本 | M34: 1301 | N34: 0.06 | O34: 固网及智慧家庭服务-互联网宽带接入-卫星宽带-卫星宽带服务 | P34: 1301;1302; | Q34: 固网及智慧家庭服务-互联网宽带接入-卫星宽带-卫星宽带服务;固网及智慧家庭服务-互联网宽带接入-卫星宽带-卫星资源服务 | R34: 是 | S34: 是 | T34: 需填写速率/带宽 | U34: 无需填写折扣率
A35: JTSJCPDL201910 | B35: 卫星业务 | C35: JTSJCP03108 | D35: 手机直连卫星 | E35: 否 | F35: 标品 | I35: 卫星 | R35: 是 | T35: 无需填写速率/带宽 | U35: 无需填写折扣率
A36: JTSJCPDL201909 | B36: 专线业务 | C36: JTSJCP02042 | D36: 互联网专线-500M以下 | E36: 否 | F36: 标品 | G36: 条 | H36: 线路数 | I36: 外延业务 | J36: 专线 | L36: 专线接入成本 | M36: 1320 | N36: 0.06 | O36: 固网及智慧家庭服务-互联网宽带接入-互联网专线-普通国内互联网专线收入-FTTH/O | P36: 1306;1307;1320;1321;1322;1323;1326;1329;1330;1331;2557 | Q36: 固网及智慧家庭服务-互联网宽带接入-普通宽带-装移机收入;固网及智慧家庭服务-互联网宽带接入-普通宽带-业务调测费;固网及智慧家庭服务-互联网宽带接入-互联网专线-普通国内互联网专线收入-FTTH/O;固网及智慧家庭服务-互联网宽带接入-互联网专线-普通国内互联网专线收入-ADSL;固网及智慧家庭服务-互联网宽带接入-互联网专线-普通国内互联网专线收入-LAN;固网及智慧家庭服务-互联网宽带接入-互联网专线-普通国内互联网专线收入-光纤直驱;固网及智慧家庭服务-互联网宽带接入-互联网专线-普通国内互联网专线收入-光纤直驱;固网及智慧家庭服务-互联网宽带接入-互联网专线-互联网专线安全服务（云堤）-DDoS攻击防护服务（互联网）;固网及智慧家庭服务-互联网宽带接入-互联网专线-互联网专线安全服务（云堤）-云镜;固网及智慧家庭服务-互联网宽带接入-互联网专线-商务专线;固网及智慧家庭服务-互联网宽带接入-互联网专线-国际精品专线;固网及智慧家庭服务-互联网宽带接入-其他互联网宽带接入业务-其他 | R36: 是 | S36: 是 | T36: 需填写速率/带宽 | U36: 无需填写折扣率
A37: JTSJCPDL201909 | B37: 专线业务 | C37: JTSJCP02108 | D37: 互联网专线-500M及以上 | E37: 否 | F37: 标品 | G37: 条 | H37: 线路数 | I37: 外延业务 | J37: 专线 | L37: 专线接入成本 | M37: 1320 | N37: 0.06 | O37: 固网及智慧家庭服务-互联网宽带接入-互联网专线-普通国内互联网专线收入-FTTH/O | P37: 1306;1307;1320;1321;1322;1323;1326;1329;1330;1331;2557 | Q37: 固网及智慧家庭服务-互联网宽带接入-普通宽带-装移机收入;固网及智慧家庭服务-互联网宽带接入-普通宽带-业务调测费;固网及智慧家庭服务-互联网宽带接入-互联网专线-普通国内互联网专线收入-FTTH/O;固网及智慧家庭服务-互联网宽带接入-互联网专线-普通国内互联网专线收入-ADSL;固网及智慧家庭服务-互联网宽带接入-互联网专线-普通国内互联网专线收入-LAN;固网及智慧家庭服务-互联网宽带接入-互联网专线-普通国内互联网专线收入-光纤直驱;固网及智慧家庭服务-互联网宽带接入-互联网专线-普通国内互联网专线收入-光纤直驱;固网及智慧家庭服务-互联网宽带接入-互联网专线-互联网专线安全服务（云堤）-DDoS攻击防护服务（互联网）;固网及智慧家庭服务-互联网宽带接入-互联网专线-互联网专线安全服务（云堤）-云镜;固网及智慧家庭服务-互联网宽带接入-互联网专线-商务专线;固网及智慧家庭服务-互联网宽带接入-互联网专线-国际精品专线;固网及智慧家庭服务-互联网宽带接入-其他互联网宽带接入业务-其他 | R37: 是 | S37: 是 | T37: 需填写速率/带宽 | U37: 无需填写折扣率
A38: JTSJCPDL201909 | B38: 专线业务 | C38: JTSJCP02089 | D38: 互联网国际精品专线-500M以下 | E38: 否 | F38: 标品 | G38: 条 | H38: 线路数 | I38: 外延业务 | J38: 专线 | L38: 专线接入成本 | M38: 1331 | N38: 0.06 | O38: 固网及智慧家庭服务-互联网宽带接入-互联网专线-国际精品专线 | P38: 1331 | Q38: 固网及智慧家庭服务-互联网宽带接入-互联网专线-国际精品专线 | R38: 是 | S38: 是 | T38: 需填写速率/带宽 | U38: 无需填写折扣率
A39: JTSJCPDL201909 | B39: 专线业务 | C39: JTSJCP02109 | D39: 互联网国际精品专线-500M及以上 | E39: 否 | F39: 标品 | G39: 条 | H39: 线路数 | I39: 外延业务 | J39: 专线 | L39: 专线接入成本 | M39: 1331 | N39: 0.06 | O39: 固网及智慧家庭服务-互联网宽带接入-互联网专线-国际精品专线 | P39: 1331 | Q39: 固网及智慧家庭服务-互联网宽带接入-互联网专线-国际精品专线 | R39: 是 | S39: 是 | T39: 需填写速率/带宽 | U39: 无需填写折扣率
A40: JTSJCPDL201909 | B40: 专线业务 | C40: JTSJCP02088 | D40: 商务专线 | E40: 否 | F40: 标品 | G40: 条 | H40: 线路数 | I40: 外延业务 | J40: 专线 | L40: 商务光纤接入 | M40: 1330 | N40: 0.06 | O40: 固网及智慧家庭服务-互联网宽带接入-互联网专线-商务专线 | P40: 1330 | Q40: 固网及智慧家庭服务-互联网宽带接入-互联网专线-商务专线 | R40: 是 | S40: 是 | T40: 需填写速率/带宽 | U40: 无需填写折扣率
...

Sheet 税率配置表&利润中心
A1: 指标编码 | B1: 指标名称 | C1: 税率 | D1: 税目（默认带出） | F1: 备注 | G1: 利润中心
A2: 1006 | B2: 移动通信服务-移动语音-语音收入-国内通话费 | C2: 0.09 | D2: 电信业——基础电信服务——语音服务 | G2: 总部部门
A3: 3155 | B3: 移动通信服务-移动语音-语音收入-国际、港澳台通话费 | C3: 0.09 | D3: 电信业——基础电信服务——语音服务 | G3: 工程建设中心
A4: 3156 | B4: 移动通信服务-移动语音-语音收入-国际、港澳台漫游费通话费-漫游语音包通话费 | C4: 0.09 | D4: 电信业——基础电信服务——语音服务 | G4: 市场部
A5: 3157 | B5: 移动通信服务-移动语音-语音收入-国际、港澳台漫游费通话费-漫游非语音包通话费 | C5: 0.09 | D5: 电信业——基础电信服务——语音服务 | G5: 渠道运营支撑中心（待迁移）
A6: 1024 | B6: 移动通信服务-移动语音-语音收入-移动语音结算-移动语音上市非上市结算 | C6: 0.09 | D6: 电信业——基础电信服务——语音服务 | G6: 云网运营部
A7: 1027 | B7: 移动通信服务-移动语音-语音收入-移动语音结算-移动语音漫游结算 | C7: 0.09 | D7: 电信业——基础电信服务——语音服务 | G7: 上海电信信息世界
A8: 1031 | B8: 移动通信服务-移动语音-语音收入-移动语音结算-移动语音网间结算-国内运营商网间结算-本地网网间结算-中国移动 | C8: 0.09 | D8: 电信业——基础电信服务——语音服务 | G8: 政企事业群
A9: 1032 | B9: 移动通信服务-移动语音-语音收入-移动语音结算-移动语音网间结算-国内运营商网间结算-本地网网间结算-中国联通 | C9: 0.09 | D9: 电信业——基础电信服务——语音服务 | G9: 上海电信EDI分公司
A10: 1967 | B10: 移动通信服务-移动语音-语音收入-移动语音结算-移动语音网间结算-国内运营商网间结算-本地网网间结算-中国广电 | C10: 0.09 | D10: 电信业——基础电信服务——语音服务 | G10: 业创中心
A11: 1034 | B11: 移动通信服务-移动语音-语音收入-移动语音结算-移动语音网间结算-国内运营商网间结算-国内长途网间结算-中国移动 | C11: 0.09 | D11: 电信业——基础电信服务——语音服务 | G11: 上海公司融合创新研发基地
A12: 1035 | B12: 移动通信服务-移动语音-语音收入-移动语音结算-移动语音网间结算-国内运营商网间结算-国内长途网间结算-中国联通 | C12: 0.09 | D12: 电信业——基础电信服务——语音服务 | G12: 总部集中控制
A13: 2037 | B13: 移动通信服务-移动语音-语音收入-移动语音结算-移动语音网间结算-国内运营商网间结算-国内长途网间结算-中国广电 | C13: 0.09 | D13: 电信业——基础电信服务——语音服务 | G13: 东区局分公司
A14: 1036 | B14: 移动通信服务-移动语音-语音收入-移动语音结算-移动语音网间结算-国际、港澳台运营商网间结算 | C14: 0 | D14: 免税收入 | E14: 免税收入 | F14: 关注 | G14: 南区局分公司
A15: 1037 | B15: 移动通信服务-移动语音-语音收入-移动语音结算-国际及港澳台运营商漫游结算 | C15: 0 | D15: 免税收入 | E15: 免税收入 | F15: 关注 | G15: 西区局分公司
A16: 2961 | B16: 移动通信服务-移动语音-其他 | C16: 0.09 | D16: 电信业——基础电信服务——语音服务 | G16: 北区局分公司
A17: 1042 | B17: 移动通信服务-手机上网-套内流量 | C17: 0.06 | D17: 电信业——增值电信服务——互联网接入服务 | G17: 中区局分公司
A18: 1043 | B18: 移动通信服务-手机上网-套外标准资费 | C18: 0.06 | D18: 电信业——增值电信服务——互联网接入服务 | G18: 浦东局分公司
A19: 2702 | B19: 移动通信服务-手机上网-流量包-权益包模式流量包 | C19: 0.06 | D19: 电信业——增值电信服务——互联网接入服务 | G19: 宝山局分公司
A20: 2703 | B20: 移动通信服务-手机上网-流量包-非权益包模式流量包 | C20: 0.06 | D20: 电信业——增值电信服务——互联网接入服务 | G20: 莘闵局分公司
A21: 1046 | B21: 移动通信服务-手机上网-定向流量-权益包模式定向流量 | C21: 0.06 | D21: 电信业——增值电信服务——互联网接入服务 | G21: 嘉定局分公司
A22: 1047 | B22: 移动通信服务-手机上网-定向流量-非权益包模式定向流量 | C22: 0.06 | D22: 电信业——增值电信服务——互联网接入服务 | G22: 奉贤局分公司
A23: 1049 | B23: 移动通信服务-手机上网-后向流量-后向定向流量 | C23: 0.06 | D23: 电信业——增值电信服务——互联网接入服务 | G23: 金山局分公司
A24: 1052 | B24: 移动通信服务-手机上网-后向流量-后向非定向流量 | C24: 0.06 | D24: 电信业——增值电信服务——互联网接入服务 | G24: 青浦局分公司
A25: 2962 | B25: 移动通信服务-手机上网-移动数据漫游-国际及港澳台漫游流量包 | C25: 0.06 | D25: 电信业——增值电信服务——互联网接入服务 | G25: 松江局分公司
A26: 3158 | B26: 移动通信服务-手机上网-移动数据漫游-国际及港澳台漫游非流量包 | C26: 0.06 | D26: 电信业——增值电信服务——互联网接入服务 | G26: 崇明局分公司
A27: 1085 | B27: 移动通信服务-手机上网-移动数据结算-网内结算-移动流量漫游结算 | C27: 0.06 | D27: 电信业——增值电信服务——互联网接入服务 | G27: 移互部/移动网优中心/上海5G共建共享工
A28: 1086 | B28: 移动通信服务-手机上网-移动数据结算-网内结算-天翼宽带漫游结算 | C28: 0.06 | D28: 电信业——增值电信服务——互联网接入服务 | G28: 信网部/互联网大客户部
A29: 2673 | B29: 移动通信服务-手机上网-移动数据结算-国际、港澳台漫游结算 | C29: 0 | D29: 免税收入 | E29: 免税收入 | F29: 关注 | G29: 数字生活部/互联网部
A30: 1060 | B30: 移动通信服务-手机上网-其他 | C30: 0.06 | D30: 电信业——增值电信服务——互联网接入服务 | G30: 智慧商务部/号百公司
A31: 3159 | B31: 移动通信服务-移动消息-短彩信收入-短信-发国内点对点短信收入 | C31: 0.06 | D31: 电信业——增值电信服务——短彩信服务 | G31: 罗泾信息网络中心
A32: 3160 | B32: 移动通信服务-移动消息-短彩信收入-短信-发国际、港澳台点对点短信收入 | C32: 0.06 | D32: 电信业——增值电信服务——短彩信服务 | G32: 桃浦信息网络中心
A33: 3161 | B33: 移动通信服务-移动消息-短彩信收入-短信-国际、港澳台漫游短信收入 | C33: 0.06 | D33: 电信业——增值电信服务——短彩信服务 | G33: 数字政务服务中心
A34: 2705 | B34: 移动通信服务-移动消息-短彩信收入-短信-SP短信信息费收入-收入（大收） | C34: 0.06 | D34: 电信业——增值电信服务——短彩信服务 | G34: 上海公司智慧家庭运营中心
A35: 1074 | B35: 移动通信服务-移动消息-短彩信收入-短信-SP短信信息费收入-CP/SP结算支出 | C35: 0.06 | D35: 电信业——增值电信服务——短彩信服务 | G35: 卓青信息网络中心
A36: 1075 | B36: 移动通信服务-移动消息-短彩信收入-彩信 | C36: 0.06 | D36: 电信业——增值电信服务——短彩信服务 | G36: 泖南数据服务分部
A37: 1968 | B37: 移动通信服务-移动消息-个人5G消息 | C37: 0.06 | D37: 电信业——增值电信服务——短彩信服务 | G37: 金泽数据服务分部
A38: 1165 | B38: 移动通信服务-移动消息-信息订制（净收）-收入（大收） | C38: 0.06 | D38: 电信业——增值电信服务——电子数据和信息的传输及应用服务 | G38: 机动局
A39: 1166 | B39: 移动通信服务-移动消息-信息订制（净收）-CP/SP结算支出 | C39: 0.06 | D39: 电信业——增值电信服务——电子数据和信息的传输及应用服务 | G39: 业务管理支撑中心
A40: 1080 | B40: 移动通信服务-移动消息-行业类消息-行业短彩信-行业短信 | C40: 0.06 | D40: 电信业——增值电信服务——短彩信服务 | G40: 信息园区开发建设部/房屋与土地资产运营中
...

Sheet 业务模式和列收方式判断规则
A1: 业务模式 | B1: 列收方式（总额/净额） | C1: 列收方式（非周期型） | D1: 列收方式（投入/产出） | F1: 业务模式 | G1: 列收方式（总额/净额） | H1: 列收方式（周期型）
A2: 设备经销商租赁 | B2: 总额法、时点法 | C2: 非周期型 | F2: 投资-经营租赁 | G2: 总额法、时段法 | H2: 周期型
A3: 设备买卖 | B3: 总额法、时点法 | C3: 非周期型 | F3: 投资-集成服务 | G3: 总额法、时段法 | H3: 周期型
A4: 设备受托代购 | B4: 净额法、时点法 | C4: 非周期型 | F4: 服务整合 | G4: 总额法、时段法 | H4: 周期型
A5: 设备转租赁 | B5: 净额法、时点法 | C5: 非周期型 | F5: 服务代理 | G5: 净额法、时段法 | H5: 周期型
A6: 服务整合 | B6: 总额法、时段法 | C6: 非周期型 | D6: 投入法/产出法 | F6: 设备与第三方合作 | G6: 净额法、时段法 | H6: 周期型
A7: 服务整合 | B7: 总额法、时点法 | C7: 非周期型
A8: 服务代理 | B8: 净额法、时段法 | C8: 非周期型 | D8: 产出法
A9: 服务代理 | B9: 净额法、时点法 | C9: 非周期型
A10: 设备与第三方合作 | B10: 净额法、时段法 | C10: 非周期型 | D10: 产出法
A11: 设备与第三方合作 | B11: 净额法、时点法 | C11: 非周期型
A14: 业务模式与列收方式-非周期 | C14: 业务模式与列收方式-周期
A15: 服务整合、总额法、时段法、投入法 | C15: 投资-经营租赁、总额法、时段法
A16: 服务整合、总额法、时段法、产出法 | C16: 投资-集成服务、总额法、时段法
A17: 服务整合、总额法、时点法 | C17: 服务整合、总额法、时段法
A18: 服务代理、净额法、时段法、产出法 | C18: 服务代理、净额法、时段法
A19: 服务代理、净额法、时点法 | C19: 设备与第三方合作、净额法、时段法
A20: 设备买卖、总额法、时点法
A21: 设备受托代购、净额法、时点法
A22: 设备经销商租赁、总额法、时点法
A23: 设备转租赁、净额法、时点法
A24: 设备与第三方合作、净额法、时段法、产出法
A25: 设备与第三方合作、净额法、时点法
